Workbook

Sheet 2 ALIYAH A
A1: No. Tamrin | B1: Nama | C1: No. Stambuk | D1: JML Siswi | E1: تفسير الجلالين | G1: إتمام الدراية | H1: رياض الصالحين | I1: كفاية العوام | J1: فتح المعين | K1: تسهيل الطرقات | L1: مبادئ قواعد الفقهية | M1: عدة الفارض | N1: الفية ابن مالك | O1: بداية الهداية | P1: الخط \ الإملاء | Q1: قراءة الكتب | R1: المحافظة | S1: الأخلاق | T1: جمل أرقام الدرجات الدراسية | U1: بإذن | V1: بغيره
A2: 01 | B2: AINA NUR LAELY | C2: 2788 | D2: 01 | E2: =TEXT(F2,"[$-2000000]0") -> ٥ | F2: 5 | G2: 5 | H2: 7 | I2: 6 | J2: 6 | K2: 6 | L2: - | M2: 7 | N2: 7 | O2: 6 | P2: 7 | Q2: 7 | R2: 8 | S2: 8 | T2: =SUM(E2:S2) -> 85 | U2: 1 | V2: -
A3: 02 | B3: AMARATUS SAIDA | C3: 2725 | D3: 02 | E3: =TEXT(F3,"[$-2000000]0") -> ٩ | F3: 9 | G3: 6 | H3: 8 | I3: 9 | J3: 9 | K3: 9 | L3: - | M3: 8 | N3: 6 | O3: 9 | P3: 8 | Q3: 8 | R3: 8 | S3: 8 | T3: =SUM(E3:S3) -> 105 | U3: - | V3: 1
A4: 03 | B4: ANJALI ISNA HUSNAWATI | C4: 2885 | D4: 03 | E4: =TEXT(F4,"[$-2000000]0") -> ٧ | F4: 7 | G4: 9 | H4: 8 | I4: 7 | J4: 9 | K4: 7 | L4: - | M4: 9 | N4: 8 | O4: 6 | P4: 8 | Q4: 8 | R4: 8 | S4: 8 | T4: =SUM(E4:S4) -> 102 | U4: - | V4: -
A5: 04 | B5: DAILLATS TSOORAYA | C5: 2653 | D5: 04 | E5: =TEXT(F5,"[$-2000000]0") -> ٩ | F5: 9 | G5: 9 | H5: 9 | I5: 9 | J5: 9 | K5: 9 | L5: - | M5: 9 | N5: 9 | O5: 9 | P5: 8 | Q5: 8 | R5: 8 | S5: 8 | T5: =SUM(E5:S5) -> 113 | U5: - | V5: -
A6: 05 | B6: DEWI NUR AZIZAH | C6: 2822 | D6: 05 | E6: =TEXT(F6,"[$-2000000]0") -> ٦ | F6: 6 | G6: 6 | H6: 7 | I6: 5 | J6: 5 | K6: 6 | L6: - | M6: 5 | N6: 6 | O6: 7 | P6: 8 | Q6: 7 | R6: 8 | S6: 8 | T6: =SUM(E6:S6) -> 84 | U6: - | V6: 1
A7: 06 | B7: DINA YULIANA SARI | C7: 2855 | D7: 06 | E7: =TEXT(F7,"[$-2000000]0") -> ٦ | F7: 6 | G7: 5 | H7: 6 | I7: 6 | J7: 5 | K7: 5 | L7: - | M7: 8 | N7: 5 | O7: 7 | P7: 8 | Q7: 7 | R7: 8 | S7: 8 | T7: =SUM(E7:S7) -> 84 | U7: 1 | V7: -
A8: 07 | B8: FARWAH FATIMAH FARZANI | C8: 2889 | D8: 07 | E8: =TEXT(F8,"[$-2000000]0") -> ٨ | F8: 8 | G8: 9 | H8: 9 | I8: 9 | J8: 9 | K8: 9 | L8: - | M8: 6 | N8: 9 | O8: 9 | P8: 8 | Q8: 8 | R8: 8 | S8: 8 | T8: =SUM(E8:S8) -> 109 | U8: 4 | V8: -
A9: 08 | B9: FATIN KHAMAMA | C9: 2692 | D9: 08 | E9: =TEXT(F9,"[$-2000000]0") -> ٩ | F9: 9 | G9: 9 | H9: 9 | I9: 9 | J9: 9 | K9: 9 | L9: - | M9: 9 | N9: 9 | O9: 9 | P9: 8 | Q9: 8 | R9: 8 | S9: 7 | T9: =SUM(E9:S9) -> 112 | U9: - | V9: -
A10: 09 | B10: FIKRIYA NAJITAMA | C10: 2654 | D10: 09 | E10: =TEXT(F10,"[$-2000000]0") -> ٦ | F10: 6 | G10: 5 | H10: 6 | I10: 5 | J10: 5 | K10: 6 | L10: - | M10: 5 | N10: 6 | O10: 6 | P10: 7 | Q10: 7 | R10: 7 | S10: 8 | T10: =SUM(E10:S10) -> 79 | U10: 2 | V10: -
A11: 10 | B11: FINA HIKMATUL MAULA | C11: 2732 | D11: 10 | E11: =TEXT(F11,"[$-2000000]0") -> ٩ | F11: 9 | G11: 7 | H11: 9 | I11: 7 | J11: 9 | K11: 9 | L11: - | M11: 8 | N11: 8 | O11: 9 | P11: 8 | Q11: 8 | R11: 8 | S11: 8 | T11: =SUM(E11:S11) -> 107 | U11: - | V11: -
A12: 11 | B12: FIRDA AYU NUR AMALIA | C12: 2859 | D12: 11 | E12: =TEXT(F12,"[$-2000000]0") -> ٦ | F12: 6 | G12: 5 | H12: 7 | I12: 5 | J12: 5 | K12: 7 | L12: - | M12: 5 | N12: 7 | O12: 5 | P12: 7 | Q12: 7 | R12: 7 | S12: 8 | T12: =SUM(E12:S12) -> 81 | U12: 2 | V12: -
A13: 12 | B13: FUTIKHATUL JANNAH | C13: 2890 | D13: 12 | E13: =TEXT(F13,"[$-2000000]0") -> ٥ | F13: 5 | G13: 5 | H13: 6 | I13: 5 | J13: 5 | K13: 5 | L13: - | M13: 6 | N13: 6 | O13: 6 | P13: 8 | Q13: 7 | R13: 7 | S13: 8 | T13: =SUM(E13:S13) -> 79 | U13: - | V13: -
A14: 13 | B14: HANIFAH KAFFA ARIFAH | C14: 2891 | D14: 13 | E14: =TEXT(F14,"[$-2000000]0") -> ٥ | F14: 5 | G14: 6 | H14: 7 | I14: 5 | J14: 5 | K14: 5 | L14: - | M14: 6 | N14: 5 | O14: 5 | P14: 7 | Q14: 7 | R14: 7 | S14: 8 | T14: =SUM(E14:S14) -> 78 | U14: - | V14: 2
A15: 14 | B15: JESICA BARBERA AISYAH PADANGENG ALAM | C15: 2657 | D15: 14 | E15: =TEXT(F15,"[$-2000000]0") -> ٩ | F15: 9 | G15: 8 | H15: 8 | I15: 9 | J15: 8 | K15: 9 | L15: - | M15: 9 | N15: 9 | O15: 8 | P15: 8 | Q15: 8 | R15: 8 | S15: 8 | T15: =SUM(E15:S15) -> 109 | U15: 3 | V15: -
A16: 15 | B16: KHOIRUNISA | C16: 2765 | D16: 15 | E16: =TEXT(F16,"[$-2000000]0") -> ٦ | F16: 6 | G16: 5 | H16: 6 | I16: 5 | J16: 5 | K16: 5 | L16: - | M16: 5 | N16: 7 | O16: 7 | P16: 7 | Q16: 8 | R16: 8 | S16: 8 | T16: =SUM(E16:S16) -> 82 | U16: - | V16: -
A17: 16 | B17: LIA WAFIQOTUL MAULA | C17: 2699 | D17: 16 | E17: =TEXT(F17,"[$-2000000]0") -> ٩ | F17: 9 | G17: 9 | H17: 9 | I17: 8 | J17: 8 | K17: 9 | L17: - | M17: 8 | N17: 9 | O17: 8 | P17: 8 | Q17: 8 | R17: 8 | S17: 8 | T17: =SUM(E17:S17) -> 109 | U17: - | V17: -
A18: 17 | B18: MUMAYIZAH | C18: 2872 | D18: 17 | E18: =TEXT(F18,"[$-2000000]0") -> ٦ | F18: 6 | G18: 7 | H18: 8 | I18: 5 | J18: 6 | K18: 7 | L18: - | M18: 7 | N18: 9 | O18: 8 | P18: 8 | Q18: 8 | R18: 8 | S18: 8 | T18: =SUM(E18:S18) -> 95 | U18: - | V18: -
A19: 18 | B19: NASYWA NAZWA | C19: 2837 | D19: 18 | E19: =TEXT(F19,"[$-2000000]0") -> ٧ | F19: 7 | G19: 5 | H19: 7 | I19: 6 | J19: 9 | K19: 5 | L19: - | M19: 8 | N19: 5 | O19: 5 | P19: 8 | Q19: 7 | R19: 8 | S19: 8 | T19: =SUM(E19:S19) -> 88 | U19: 1 | V19: -
A20: 19 | B20: NIRMALA | C20: 2901 | D20: 19 | E20: =TEXT(F20,"[$-2000000]0") -> ٩ | F20: 9 | G20: 6 | H20: 9 | I20: 6 | J20: 6 | K20: 6 | L20: - | M20: 7 | N20: 6 | O20: 6 | P20: 8 | Q20: 8 | R20: 8 | S20: 8 | T20: =SUM(E20:S20) -> 93 | U20: - | V20: 1
A21: 20 | B21: NUR FADILAH | C21: 2697 | D21: 20 | E21: =TEXT(F21,"[$-2000000]0") -> ٥ | F21: 5 | G21: 5 | H21: 5 | I21: 5 | J21: 5 | K21: 6 | L21: - | M21: 5 | N21: 5 | O21: 6 | P21: 8 | Q21: 8 | R21: 8 | S21: 8 | T21: =SUM(E21:S21) -> 79 | U21: - | V21: -
A22: 21 | B22: PASYA TIFANI | C22: 2670 | D22: 21 | E22: =TEXT(F22,"[$-2000000]0") -> ٧ | F22: 7 | G22: 6 | H22: 8 | I22: 6 | J22: 6 | K22: 8 | L22: - | M22: 6 | N22: 6 | O22: 8 | P22: 8 | Q22: 7 | R22: 7 | S22: 8 | T22: =SUM(E22:S22) -> 91 | U22: - | V22: -
A23: 22 | B23: QURROTUL AINI | C23: 2779 | D23: 22 | E23: =TEXT(F23,"[$-2000000]0") -> ٧ | F23: 7 | G23: 6 | H23: 7 | I23: 6 | J23: 5 | K23: 5 | L23: - | M23: 6 | N23: 5 | O23: 7 | P23: 8 | Q23: 7 | R23: 8 | S23: 8 | T23: =SUM(E23:S23) -> 85 | U23: - | V23: 1
A24: 23 | B24: RETA PUTRI AMALIA | C24: 2674 | D24: 23 | E24: =TEXT(F24,"[$-2000000]0") -> ٥ | F24: 5 | G24: 5 | H24: 5 | I24: 5 | J24: 4 | K24: 4 | L24: - | M24: 5 | N24: 5 | O24: 5 | P24: 7 | Q24: 7 | R24: 7 | S24: 8 | T24: =SUM(E24:S24) -> 72 | U24: - | V24: -
A25: 24 | B25: ROYDHOTUL MAGHFIROH | C25: 2675 | D25: 24 | E25: =TEXT(F25,"[$-2000000]0") -> ٥ | F25: 5 | G25: 8 | H25: 7 | I25: 6 | J25: 7 | K25: 6 | L25: - | M25: 7 | N25: 6 | O25: 8 | P25: 7 | Q25: 7 | R25: 7 | S25: 7 | T25: =SUM(E25:S25) -> 88 | U25: - | V25: -
A26: 25 | B26: SAILYN NAJA | C26: 2748 | D26: 25 | E26: =TEXT(F26,"[$-2000000]0") -> ٨ | F26: 8 | G26: 6 | H26: 9 | I26: 7 | J26: 7 | K26: 5 | L26: - | M26: 9 | N26: 8 | O26: 6 | P26: 8 | Q26: 8 | R26: 8 | S26: 8 | T26: =SUM(E26:S26) -> 97 | U26: - | V26: -
A27: 26 | B27: SALAMAH NAILUL MUNA | C27: 2677 | D27: 26 | E27: =TEXT(F27,"[$-2000000]0") -> ٩ | F27: 9 | G27: 9 | H27: 9 | I27: 9 | J27: 9 | K27: 9 | L27: - | M27: 9 | N27: 9 | O27: 9 | P27: 8 | Q27: 8 | R27: 8 | S27: 8 | T27: =SUM(E27:S27) -> 113 | U27: 8 | V27: -
A28: 27 | B28: SOFWI SAIDATIL UKHROWIYAH | C28: 2848 | D28: 27 | E28: =TEXT(F28,"[$-2000000]0") -> ٨ | F28: 8 | G28: 7 | H28: 9 | I28: 6 | J28: 6 | K28: 6 | L28: - | M28: 8 | N28: 7 | O28: 7 | P28: 8 | Q28: 8 | R28: 8 | S28: 8 | T28: =SUM(E28:S28) -> 96 | U28: - | V28: -
A29: 28 | B29: VIERA ADELIA PUTRI | C29: 2714 | D29: 28 | E29: =TEXT(F29,"[$-2000000]0") -> ٩ | F29: 9 | G29: 7 | H29: 8 | I29: 9 | J29: 8 | K29: 8 | L29: - | M29: 9 | N29: 8 | O29: 6 | P29: 8 | Q29: 8 | R29: 8 | S29: 8 | T29: =SUM(E29:S29) -> 104 | U29: - | V29: -
A30: 29 | B30: VINA AEINUL MAWADAH | C30: 2716 | D30: 29 | E30: =TEXT(F30,"[$-2000000]0") -> ٥ | F30: 5 | G30: 7 | H30: 7 | I30: 5 | J30: 5 | K30: 5 | L30: - | M30: 6 | N30: 5 | O30: 6 | P30: 8 | Q30: 7 | R30: 8 | S30: 8 | T30: =SUM(E30:S30) -> 82 | U30: - | V30: -
A31: 30 | B31: ZAHWA FARADISA LA’LA’AL HAQ AL-ANIZA | C31: 2916 | D31: 30 | E31: =TEXT(F31,"[$-2000000]0") -> ٩ | F31: 9 | G31: 9 | H31: 9 | I31: 9 | J31: 8 | K31: 9 | L31: - | M31: 8 | N31: 9 | O31: 9 | P31: 8 | Q31: 8 | R31: 8 | S31: 8 | T31: =SUM(E31:S31) -> 111 | U31: 1 | V31: 2
B32: NILAI 'AM | E32: =TEXT(F32,"[$-2000000]0") -> ٢١٣ | F32: =SUM(F2:F31) -> 213 | G32: =SUM(G2:G31) -> 201 | H32: =SUM(H2:H31) -> 228 | I32: =SUM(I2:I31) -> 199 | J32: =SUM(J2:J31) -> 202 | K32: =SUM(K2:K31) -> 204 | L32: - | M32: =SUM(M2:M31) -> 213 | N32: =SUM(N2:N31) -> 209 | O32: =SUM(O2:O31) -> 212 | P32: =SUM(P2:P31) -> 233 | Q32: =SUM(Q2:Q31) -> 227 | R32: =SUM(R2:R31) -> 233 | S32: =SUM(S2:S31) -> 238 | T32: =SUM(E32:S32) -> 2812 | U32: - | V32: -
H36: NILAI 'AM
H37: =E32/D31 -> 7
H38: =G32/D31 -> 7
H39: =H32/D31 -> 8
H40: =I32/D31 -> 7
H41: =J32/D31 -> 7
H42: =K32/D31 -> 7
H43: -
...

Sheet 2 ALIYAH B
A1: No. Tamrin | B1: Nama | C1: No. Stambuk | D1: JML Siswi | E1: تفسير الجلالين | G1: إتمام الدراية | H1: رياض الصالحين | I1: كفاية العوام | J1: فتح المعين | K1: تسهيل الطرقات | L1: مبادئ قواعد الفقهية | M1: عدة الفارض | N1: الفية ابن مالك | O1: بداية الهداية | P1: الخط \ الإملاء | Q1: قراءة الكتب | R1: المحافظة | S1: الأخلاق | T1: جمل أرقام الدرجات الدراسية | U1: بإذن | V1: بغيره
A2: 01 | B2: AINUN NISA | C2: 2884 | D2: 01 | E2: =TEXT(F2,"[$-2000000]0") -> ٩ | F2: 9 | G2: 7 | H2: 7 | I2: 6 | J2: 7 | K2: 6 | L2: - | M2: 7 | N2: 7 | O2: 8 | P2: 8 | Q2: 8 | R2: 8 | S2: 7 | T2: =SUM(E2:S2) -> 95 | U2: - | V2: 8
A3: 02 | B3: ALLENTHA SHEYNA LUNAURA Y. P. | C3: 2722 | D3: 02 | E3: =TEXT(F3,"[$-2000000]0") -> ٩ | F3: 9 | G3: 9 | H3: 9 | I3: 8 | J3: 8 | K3: 8 | L3: - | M3: 7 | N3: 8 | O3: 9 | P3: 8 | Q3: 8 | R3: 8 | S3: 8 | T3: =SUM(E3:S3) -> 107 | U3: - | V3: 1
A4: 03 | B4: BINTI MARDLOTILLAH | C4: 2652 | D4: 03 | E4: =TEXT(F4,"[$-2000000]0") -> ٩ | F4: 9 | G4: 9 | H4: 9 | I4: 9 | J4: 9 | K4: 9 | L4: - | M4: 9 | N4: 9 | O4: 9 | P4: 8 | Q4: 8 | R4: 8 | S4: 8 | T4: =SUM(E4:S4) -> 113 | U4: - | V4: -
A5: 04 | B5: CHANINA KAMELIA MAHFUDZOTUSSALAMAH | C5: 2796 | D5: 04 | E5: =TEXT(F5,"[$-2000000]0") -> ٩ | F5: 9 | G5: 9 | H5: 9 | I5: 9 | J5: 9 | K5: 9 | L5: - | M5: 9 | N5: 9 | O5: 9 | P5: 8 | Q5: 8 | R5: 8 | S5: 8 | T5: =SUM(E5:S5) -> 113 | U5: 4 | V5: -
A6: 05 | B6: DHOU'UHA YUDHI'U FALABIQOH | C6: 2799 | D6: 05 | E6: =TEXT(F6,"[$-2000000]0") -> ٩ | F6: 9 | G6: 9 | H6: 9 | I6: 9 | J6: 9 | K6: 8 | L6: - | M6: 9 | N6: 9 | O6: 9 | P6: 8 | Q6: 8 | R6: 8 | S6: 8 | T6: =SUM(E6:S6) -> 112 | U6: - | V6: -
A7: 06 | B7: EFI ZULIYANI | C7: 2730 | D7: 06 | E7: =TEXT(F7,"[$-2000000]0") -> ٧ | F7: 7 | G7: 6 | H7: 9 | I7: 7 | J7: 7 | K7: 7 | L7: - | M7: 9 | N7: 8 | O7: 7 | P7: 8 | Q7: 8 | R7: 8 | S7: 7 | T7: =SUM(E7:S7) -> 98 | U7: - | V7: -
A8: 07 | B8: FARICHA NAJLA NADIA | C8: 2690 | D8: 07 | E8: =TEXT(F8,"[$-2000000]0") -> ٦ | F8: 6 | G8: 6 | H8: 9 | I8: 6 | J8: 7 | K8: 6 | L8: - | M8: 9 | N8: 6 | O8: 7 | P8: 8 | Q8: 7 | R8: 7 | S8: 7 | T8: =SUM(E8:S8) -> 91 | U8: 2 | V8: -
A9: 08 | B9: HANIN ATIQOTUR RIF'AH SHODIQ | C9: 2761 | D9: 08 | E9: =TEXT(F9,"[$-2000000]0") -> ٦ | F9: 6 | G9: 6 | H9: 8 | I9: 6 | J9: 6 | K9: 7 | L9: - | M9: 6 | N9: 6 | O9: 7 | P9: 8 | Q9: 7 | R9: 7 | S9: 8 | T9: =SUM(E9:S9) -> 88 | U9: - | V9: -
A10: 09 | B10: HUMAIRO' ALMUFIDAH | C10: 2892 | D10: 09 | E10: =TEXT(F10,"[$-2000000]0") -> ٦ | F10: 6 | G10: 6 | H10: 8 | I10: 6 | J10: 5 | K10: 7 | L10: - | M10: 6 | N10: 6 | O10: 7 | P10: 7 | Q10: 7 | R10: 7 | S10: 8 | T10: =SUM(E10:S10) -> 86 | U10: 3 | V10: -
A11: 10 | B11: INDAH ASHLIHAH AZMIROTUSSALAMAH | C11: 2762 | D11: 10 | E11: =TEXT(F11,"[$-2000000]0") -> ٦ | F11: 6 | G11: 5 | H11: 7 | I11: 5 | J11: 8 | K11: 6 | L11: - | M11: 7 | N11: 5 | O11: 5 | P11: 7 | Q11: 6 | R11: 7 | S11: 8 | T11: =SUM(E11:S11) -> 82 | U11: 2 | V11: -
A12: 11 | B12: ISNIATUN | C12: 2805 | D12: 11 | E12: =TEXT(F12,"[$-2000000]0") -> ٥ | F12: 5 | G12: 5 | H12: 7 | I12: 5 | J12: 5 | K12: 5 | L12: - | M12: 7 | N12: 5 | O12: 5 | P12: 6 | Q12: 6 | R12: 6 | S12: 7 | T12: =SUM(E12:S12) -> 74 | U12: - | V12: -
A13: 12 | B13: LAURA NASIKA FATMA PADANGENG WULAN | C13: 2698 | D13: 12 | E13: =TEXT(F13,"[$-2000000]0") -> ٨ | F13: 8 | G13: 7 | H13: 9 | I13: 6 | J13: 8 | K13: 6 | L13: - | M13: 6 | N13: 9 | O13: 8 | P13: 8 | Q13: 8 | R13: 8 | S13: 8 | T13: =SUM(E13:S13) -> 99 | U13: 2 | V13: -
A14: 13 | B14: LIYAL HUSNA WAZIYADA | C14: 2700 | D14: 13 | E14: =TEXT(F14,"[$-2000000]0") -> ٨ | F14: 8 | G14: 9 | H14: 9 | I14: 9 | J14: 9 | K14: 9 | L14: - | M14: 8 | N14: 9 | O14: 7 | P14: 8 | Q14: 8 | R14: 8 | S14: 8 | T14: =SUM(E14:S14) -> 109 | U14: - | V14: -
A15: 14 | B15: MAHBUBATUL JANAH | C15: 2660 | D15: 14 | E15: =TEXT(F15,"[$-2000000]0") -> ٩ | F15: 9 | G15: 9 | H15: 9 | I15: 9 | J15: 9 | K15: 9 | L15: - | M15: 9 | N15: 9 | O15: 8 | P15: 8 | Q15: 8 | R15: 8 | S15: 8 | T15: =SUM(E15:S15) -> 112 | U15: - | V15: -
A16: 15 | B16: MAISAROH | C16: 2701 | D16: 15 | E16: =TEXT(F16,"[$-2000000]0") -> ٩ | F16: 9 | G16: 8 | H16: 9 | I16: 7 | J16: 8 | K16: 7 | L16: - | M16: 8 | N16: 9 | O16: 8 | P16: 7 | Q16: 8 | R16: 8 | S16: 8 | T16: =SUM(E16:S16) -> 104 | U16: 1 | V16: -
A17: 16 | B17: MEI NANGIMAH | C17: 2871 | D17: 16 | E17: =TEXT(F17,"[$-2000000]0") -> ٥ | F17: 5 | G17: 5 | H17: 8 | I17: 5 | J17: 7 | K17: 6 | L17: - | M17: 7 | N17: 6 | O17: 7 | P17: 7 | Q17: 7 | R17: 8 | S17: 7 | T17: =SUM(E17:S17) -> 85 | U17: - | V17: -
A18: 17 | B18: MINKKA QISTHY AL HIMNA | C18: 2702 | D18: 17 | E18: =TEXT(F18,"[$-2000000]0") -> ٩ | F18: 9 | G18: 9 | H18: 9 | I18: 8 | J18: 8 | K18: 8 | L18: - | M18: 8 | N18: 9 | O18: 7 | P18: 8 | Q18: 8 | R18: 8 | S18: 8 | T18: =SUM(E18:S18) -> 107 | U18: 1 | V18: -
A19: 18 | B19: NAFIATUD DAROINI | C19: 2664 | D19: 18 | E19: =TEXT(F19,"[$-2000000]0") -> ٩ | F19: 9 | G19: 9 | H19: 8 | I19: 8 | J19: 8 | K19: 7 | L19: - | M19: 9 | N19: 9 | O19: 8 | P19: 8 | Q19: 8 | R19: 8 | S19: 8 | T19: =SUM(E19:S19) -> 107 | U19: 6 | V19: -
A20: 19 | B20: NAILUN NAJAH ALJADIDAH | C20: 2704 | D20: 19 | E20: =TEXT(F20,"[$-2000000]0") -> ٩ | F20: 9 | G20: 9 | H20: 9 | I20: 8 | J20: 9 | K20: 7 | L20: - | M20: 9 | N20: 9 | O20: 7 | P20: 8 | Q20: 8 | R20: 8 | S20: 8 | T20: =SUM(E20:S20) -> 108 | U20: 1 | V20: -
A21: 20 | B21: NIDA RAHMA KHASANI | C21: 2900 | D21: 20 | E21: =TEXT(F21,"[$-2000000]0") -> ٧ | F21: 7 | G21: 7 | H21: 9 | I21: 6 | J21: 8 | K21: 6 | L21: - | M21: 9 | N21: 5 | O21: 8 | P21: 8 | Q21: 8 | R21: 7 | S21: 8 | T21: =SUM(E21:S21) -> 96 | U21: 3 | V21: 3
A22: 21 | B22: NIHLAH SALIMAH FIDDAROIN | C22: 2668 | D22: 21 | E22: =TEXT(F22,"[$-2000000]0") -> ٩ | F22: 9 | G22: 9 | H22: 9 | I22: 8 | J22: 9 | K22: 9 | L22: - | M22: 9 | N22: 9 | O22: 9 | P22: 8 | Q22: 8 | R22: 8 | S22: 8 | T22: =SUM(E22:S22) -> 112 | U22: 1 | V22: -
A23: 23 | B23: RIZKA TOYYIBAH | C23: 2815 | D23: 22 | E23: =TEXT(F23,"[$-2000000]0") -> ٤ | F23: 4 | G23: 5 | H23: 6 | I23: 5 | J23: 5 | K23: 4 | L23: - | M23: 5 | N23: 5 | O23: 5 | P23: 6 | Q23: 6 | R23: 7 | S23: 7 | T23: =SUM(E23:S23) -> 70 | U23: 6 | V23: 9
A24: 24 | B24: SAKINATUL AWIDDAH | C24: 2676 | D24: 23 | E24: =TEXT(F24,"[$-2000000]0") -> ٩ | F24: 9 | G24: 9 | H24: 9 | I24: 8 | J24: 7 | K24: 7 | L24: - | M24: 7 | N24: 9 | O24: 8 | P24: 8 | Q24: 8 | R24: 8 | S24: 8 | T24: =SUM(E24:S24) -> 105 | U24: - | V24: -
A25: 25 | B25: SALSA RONA ANDIRA | C25: 2678 | D25: 24 | E25: =TEXT(F25,"[$-2000000]0") -> ٦ | F25: 6 | G25: 9 | H25: 9 | I25: 5 | J25: 8 | K25: 6 | L25: - | M25: 5 | N25: 5 | O25: 8 | P25: 6 | Q25: 6 | R25: 7 | S25: 8 | T25: =SUM(E25:S25) -> 88 | U25: - | V25: -
A26: 26 | B26: SINTA ULWIYATUL HASANAH | C26: 2750 | D26: 25 | E26: =TEXT(F26,"[$-2000000]0") -> ٩ | F26: 9 | G26: 8 | H26: 9 | I26: 7 | J26: 7 | K26: 9 | L26: - | M26: 9 | N26: 8 | O26: 7 | P26: 8 | Q26: 8 | R26: 8 | S26: 8 | T26: =SUM(E26:S26) -> 105 | U26: 1 | V26: -
A27: 27 | B27: TAFRIJJIYYAH HISLAMI PUTRI | C27: 2681 | D27: 26 | E27: =TEXT(F27,"[$-2000000]0") -> ٧ | F27: 7 | G27: 9 | H27: 9 | I27: 6 | J27: 7 | K27: 8 | L27: - | M27: 7 | N27: 9 | O27: 8 | P27: 8 | Q27: 8 | R27: 8 | S27: 8 | T27: =SUM(E27:S27) -> 102 | U27: 1 | V27: 1
A28: 28 | B28: TITIK KUSUMAWATI | C28: 2682 | D28: 27 | E28: =TEXT(F28,"[$-2000000]0") -> ٩ | F28: 9 | G28: 9 | H28: 9 | I28: 9 | J28: 9 | K28: 9 | L28: - | M28: 9 | N28: 9 | O28: 9 | P28: 8 | Q28: 8 | R28: 8 | S28: 8 | T28: =SUM(E28:S28) -> 113 | U28: - | V28: 1
A29: 29 | B29: TSAABITA A'MALUNA ZAHRO' | C29: 2909 | D29: 28 | E29: =TEXT(F29,"[$-2000000]0") -> ٥ | F29: 5 | G29: 6 | H29: 8 | I29: 5 | J29: 7 | K29: 7 | L29: - | M29: 6 | N29: 5 | O29: 6 | P29: 7 | Q29: 7 | R29: 8 | S29: 8 | T29: =SUM(E29:S29) -> 85 | U29: - | V29: 1
A30: 30 | B30: TUTI ALAWIYAH | C30: 2684 | D30: 29 | E30: =TEXT(F30,"[$-2000000]0") -> ٧ | F30: 7 | G30: 9 | H30: 9 | I30: 9 | J30: 9 | K30: 9 | L30: - | M30: 8 | N30: 9 | O30: 9 | P30: 8 | Q30: 8 | R30: 7 | S30: 8 | T30: =SUM(E30:S30) -> 109 | U30: - | V30: -
A31: 31 | B31: VENITA FITRIANI | C31: 2685 | D31: 30 | E31: =TEXT(F31,"[$-2000000]0") -> ٧ | F31: 7 | G31: 5 | H31: 8 | I31: 6 | J31: 5 | K31: 5 | L31: - | M31: 6 | N31: 6 | O31: 6 | P31: 7 | Q31: 7 | R31: 8 | S31: 7 | T31: =SUM(E31:S31) -> 83 | U31: - | V31: -
A32: 32 | B32: YESICCA YAHYA ALVIA | C32: 2786 | D32: 31 | E32: =TEXT(F32,"[$-2000000]0") -> ٥ | F32: 5 | G32: 6 | H32: 8 | I32: 6 | J32: 6 | K32: 5 | L32: - | M32: 5 | N32: 6 | O32: 5 | P32: 7 | Q32: 7 | R32: 8 | S32: 8 | T32: =SUM(E32:S32) -> 82 | U32: 4 | V32: -
A33: 33 | B33: ZAHROTUL ASHFIA | C33: 2912 | D33: 32 | E33: =TEXT(F33,"[$-2000000]0") -> ٧ | F33: 7 | G33: 8 | H33: 9 | I33: 6 | J33: 6 | K33: 7 | L33: - | M33: 7 | N33: 6 | O33: 7 | P33: 7 | Q33: 7 | R33: 7 | S33: 8 | T33: =SUM(E33:S33) -> 92 | U33: - | V33: -
B34: NILAI 'AM | E34: =TEXT(F34,"[$-2000000]0") -> ٢٣٨ | F34: =SUM(F2:F33) -> 238 | G34: =SUM(G2:G33) -> 241 | H34: =SUM(H2:H33) -> 272 | I34: =SUM(I2:I33) -> 222 | J34: =SUM(J2:J33) -> 239 | K34: =SUM(K2:K33) -> 228 | L34: =SUM(L2:L33) -> 0 | M34: =SUM(M2:M33) -> 241 | ... S34: =SUM(S2:S33) -> 249 | T34: =SUM(E34:S34) -> 3132 | U34: - | V34: -
U35: - | V35: -
U36: - | V36: -
H38: NILAI 'AM
H39: =E34/D33 -> 7
H40: =G34/D33 -> 8
B41: SIT MELEBIHI BATAS | H41: =H34/D33 -> 9
...

Sheet 2 ALIYAH C
A1: No. Tamrin | B1: Nama | C1: No. Stambuk | D1: JML Siswi | E1: تفسير الجلالين | G1: إتمام الدراية | H1: رياض الصالحين | I1: كفاية العوام | J1: فتح المعين | K1: تسهيل الطرقات | L1: مبادئ قواعد الفقهية | M1: عدة الفارض | N1: الفية ابن مالك | O1: بداية الهداية | P1: الخط \ الإملاء | Q1: قراءة الكتب | R1: المحافظة | S1: الأخلاق | T1: جمل أرقام الدرجات الدراسية | U1: بإذن | V1: بغيره
A2: 01 | B2: AFIDATUL MUNAWAROH | C2: 2687 | D2: 01 | E2: =TEXT(F2,"[$-2000000]0") -> ٦ | F2: 6 | G2: 4 | H2: 6 | I2: 4 | J2: 5 | K2: 5 | L2: - | M2: 5 | N2: 5 | O2: 6 | P2: 7 | Q2: 7 | R2: 7 | S2: 8 | T2: =SUM(E2:S2) -> 75 | U2: 1
A3: 02 | B3: ARINA PUTRI AISYAH | C3: 2728 | D3: 02 | E3: =TEXT(F3,"[$-2000000]0") -> ٩ | F3: 9 | G3: 9 | H3: 9 | I3: 9 | J3: 9 | K3: 9 | L3: - | M3: 9 | N3: 9 | O3: 9 | P3: 8 | Q3: 8 | R3: 8 | S3: 8 | T3: =SUM(E3:S3) -> 113 | U3: 1 | V3: -
A4: 03 | B4: DWI NOVI ARINI | C4: 2800 | D4: 03 | E4: =TEXT(F4,"[$-2000000]0") -> ٤ | F4: 4 | G4: 7 | H4: 9 | I4: 4 | J4: 5 | K4: 6 | L4: - | M4: 7 | N4: 5 | O4: 6 | P4: 7 | Q4: 7 | R4: 8 | S4: 8 | T4: =SUM(E4:S4) -> 83 | U4: 4 | V4: -
A5: 04 | B5: FATHINA RAMADHANI | C5: 2691 | D5: 04 | E5: =TEXT(F5,"[$-2000000]0") -> ٩ | F5: 9 | G5: 9 | H5: 9 | I5: 7 | J5: 8 | K5: 9 | L5: - | M5: 9 | N5: 9 | O5: 8 | P5: 8 | Q5: 8 | R5: 8 | S5: 8 | T5: =SUM(E5:S5) -> 109 | U5: 2 | V5: -
A6: 05 | B6: FAZA KAUTSARA | C6: 2693 | D6: 05 | E6: =TEXT(F6,"[$-2000000]0") -> ٩ | F6: 9 | G6: 7 | H6: 8 | I6: 7 | J6: 6 | K6: 8 | L6: - | M6: 4 | N6: 5 | O6: 9 | P6: 7 | Q6: 8 | R6: 8 | S6: 8 | T6: =SUM(E6:S6) -> 94 | U6: 1 | V6: -
A7: 06 | B7: FAZA NAYYIROTUT THOYYIBAH AL-FAIQOH | C7: 2731 | D7: 06 | E7: =TEXT(F7,"[$-2000000]0") -> ٨ | F7: 8 | G7: 7 | H7: 9 | I7: 7 | J7: 5 | K7: 6 | L7: - | M7: 9 | N7: 9 | O7: 8 | P7: 9 | Q7: 8 | R7: 7 | S7: 8 | T7: =SUM(E7:S7) -> 100 | U7: - | V7: -
A8: 07 | B8: HARTI MINAWATI | C8: 2694 | D8: 07 | E8: =TEXT(F8,"[$-2000000]0") -> ٨ | F8: 8 | G8: 7 | H8: 8 | I8: 7 | J8: 9 | K8: 9 | L8: - | M8: 8 | N8: 6 | O8: 8 | P8: 8 | Q8: 8 | R8: 8 | S8: 8 | T8: =SUM(E8:S8) -> 102 | U8: - | V8: -
A9: 08 | B9: HILYATUL AULIYA | C9: 2828 | D9: 08 | E9: =TEXT(F9,"[$-2000000]0") -> ٩ | F9: 9 | G9: 9 | H9: 9 | I9: 9 | J9: 9 | K9: 9 | L9: - | M9: 9 | N9: 9 | O9: 9 | P9: 9 | Q9: 8 | R9: 8 | S9: 8 | T9: =SUM(E9:S9) -> 114 | U9: - | V9: -
A10: 09 | B10: INDAH CAHYAWATI | C10: 2656 | D10: 09 | E10: =TEXT(F10,"[$-2000000]0") -> ٥ | F10: 5 | G10: 8 | H10: 8 | I10: 4 | J10: 6 | K10: 6 | L10: - | M10: 7 | N10: 4 | O10: 7 | P10: 7 | Q10: 7 | R10: 6 | S10: 6 | T10: =SUM(E10:S10) -> 81 | U10: 6 | V10: 7
A11: 10 | B11: JUMROTUL KHASANAH | C11: 2695 | D11: 10 | E11: =TEXT(F11,"[$-2000000]0") -> ٨ | F11: 8 | G11: 7 | H11: 8 | I11: 7 | J11: 8 | K11: 9 | L11: - | M11: 9 | N11: 4 | O11: 8 | P11: 9 | Q11: 8 | R11: 8 | S11: 8 | T11: =SUM(E11:S11) -> 101 | U11: 1 | V11: -
A12: 11 | B12: KHADIJAH AZZAHRA | C12: 2538 | D12: 11 | E12: =TEXT(F12,"[$-2000000]0") -> ٦ | F12: 6 | G12: 4 | H12: 7 | I12: 4 | J12: 5 | K12: 6 | L12: - | M12: 4 | N12: 4 | O12: 5 | P12: 8 | Q12: 7 | R12: 8 | S12: 8 | T12: =SUM(E12:S12) -> 76 | U12: - | V12: -
A13: 12 | B13: LINAILI SYAUQIYATU ZAHRO | C13: 2767 | D13: 12 | E13: =TEXT(F13,"[$-2000000]0") -> ٩ | F13: 9 | G13: 9 | H13: 9 | I13: 8 | J13: 9 | K13: 9 | L13: - | M13: 9 | N13: 9 | O13: 9 | P13: 9 | Q13: 8 | R13: 9 | S13: 8 | T13: =SUM(E13:S13) -> 114 | U13: 1 | V13: -
A14: 13 | B14: LITA RAHMA AULIA | C14: 2735 | D14: 13 | E14: =TEXT(F14,"[$-2000000]0") -> ٩ | F14: 9 | G14: 9 | H14: 9 | I14: 8 | J14: 9 | K14: 9 | L14: - | M14: 9 | N14: 9 | O14: 8 | P14: 9 | Q14: 8 | R14: 8 | S14: 8 | T14: =SUM(E14:S14) -> 112 | U14: - | V14: -
A15: 14 | B15: MAEMUNAH RIZKY AMALIA | C15: 2894 | D15: 14 | E15: =TEXT(F15,"[$-2000000]0") -> ٨ | F15: 8 | G15: 9 | H15: 9 | I15: 8 | J15: 9 | K15: 9 | L15: - | M15: 7 | N15: 9 | O15: 9 | P15: 8 | Q15: 8 | R15: 9 | S15: 8 | T15: =SUM(E15:S15) -> 110 | U15: 5 | V15: 1
A16: 15 | B16: NAFIAH RS. | C16: 2834 | D16: 15 | E16: =TEXT(F16,"[$-2000000]0") -> ٩ | F16: 9 | G16: 9 | H16: 9 | I16: 7 | J16: 7 | K16: 9 | L16: - | M16: 7 | N16: 9 | O16: 8 | P16: 7 | Q16: 8 | R16: 8 | S16: 8 | T16: =SUM(E16:S16) -> 105 | U16: - | V16: 1
A17: 16 | B17: NAZILATUR ROKHMAH | C17: 2772 | D17: 16 | E17: =TEXT(F17,"[$-2000000]0") -> ٩ | F17: 9 | G17: 8 | H17: 9 | I17: 7 | J17: 7 | K17: 8 | L17: - | M17: 8 | N17: 9 | O17: 8 | P17: 9 | Q17: 8 | R17: 9 | S17: 8 | T17: =SUM(E17:S17) -> 107 | U17: 4 | V17: 3
A18: 17 | B18: NIDATUL QOLBIYYAH | C18: 2810 | D18: 17 | E18: =TEXT(F18,"[$-2000000]0") -> ٩ | F18: 9 | G18: 9 | H18: 9 | I18: 9 | J18: 8 | K18: 9 | L18: - | M18: 6 | N18: 9 | O18: 9 | P18: 7 | Q18: 8 | R18: 9 | S18: 7 | T18: =SUM(E18:S18) -> 108 | U18: 1 | V18: -
A19: 18 | B19: NIRAHAYU | C19: 2742 | D19: 18 | E19: =TEXT(F19,"[$-2000000]0") -> ٩ | F19: 9 | G19: 9 | H19: 9 | I19: 7 | J19: 9 | K19: 9 | L19: - | M19: 9 | N19: 8 | O19: 8 | P19: 8 | Q19: 8 | R19: 9 | S19: 8 | T19: =SUM(E19:S19) -> 110 | U19: 1 | V19: -
A20: 19 | B20: NUR HIDAYATUL KHASANAH | C20: 2707 | D20: 19 | E20: =TEXT(F20,"[$-2000000]0") -> ٩ | F20: 9 | G20: 8 | H20: 9 | I20: 8 | J20: 9 | K20: 8 | L20: - | M20: 9 | N20: 9 | O20: 9 | P20: 7 | Q20: 8 | R20: 8 | S20: 8 | T20: =SUM(E20:S20) -> 109 | U20: - | V20: -
A21: 20 | B21: NUZLAH FITRIYANI | C21: 2811 | D21: 20 | E21: =TEXT(F21,"[$-2000000]0") -> ٤ | F21: 4 | G21: 7 | H21: 9 | I21: 5 | J21: 5 | K21: 6 | L21: - | M21: 8 | N21: 5 | O21: 7 | P21: 9 | Q21: 8 | R21: 9 | S21: 8 | T21: =SUM(E21:S21) -> 90 | U21: 1 | V21: -
A22: 21 | B22: PUTRI FAJRI HIDAYAH | C22: 2512 | D22: 21 | E22: =TEXT(F22,"[$-2000000]0") -> ٨ | F22: 8 | G22: 4 | H22: 7 | I22: 4 | J22: 4 | K22: 5 | L22: - | M22: 6 | N22: 5 | O22: 6 | P22: 7 | Q22: 7 | R22: 7 | S22: 7 | T22: =SUM(E22:S22) -> 77 | U22: 2 | V22: 2
A23: 22 | B23: RAISYA PUTRI FADLILAH | C23: 2843 | D23: 22 | E23: =TEXT(F23,"[$-2000000]0") -> ٨ | F23: 8 | G23: 6 | H23: 9 | I23: 6 | J23: 7 | K23: 6 | L23: - | M23: 8 | N23: 9 | O23: 8 | P23: 9 | Q23: 7 | R23: 8 | S23: 8 | T23: =SUM(E23:S23) -> 99 | U23: - | V23: -
A24: 23 | B24: REVA FAHRA AISYYAH | C24: 2746 | D24: 23 | E24: =TEXT(F24,"[$-2000000]0") -> ٩ | F24: 9 | G24: 9 | H24: 9 | I24: 7 | J24: 9 | K24: 9 | L24: - | M24: 9 | N24: 9 | O24: 9 | P24: 9 | Q24: 9 | R24: 9 | S24: 8 | T24: =SUM(E24:S24) -> 114 | U24: - | V24: -
A25: 24 | B25: RINA OKTAVIANI | C25: 2709 | D25: 24 | E25: =TEXT(F25,"[$-2000000]0") -> ٥ | F25: 5 | G25: 9 | H25: 9 | I25: 4 | J25: 6 | K25: 7 | L25: - | M25: 8 | N25: 9 | O25: 7 | P25: 8 | Q25: 8 | R25: 8 | S25: 8 | T25: =SUM(E25:S25) -> 96 | U25: - | V25: -
A26: 25 | B26: RIZMA NOVITA RAHMA | C26: 2904 | D26: 25 | E26: =TEXT(F26,"[$-2000000]0") -> ٧ | F26: 7 | G26: 8 | H26: 9 | I26: 4 | J26: 8 | K26: 9 | L26: - | M26: 8 | N26: 4 | O26: 9 | P26: 8 | Q26: 8 | R26: 8 | S26: 7 | T26: =SUM(E26:S26) -> 97 | U26: - | V26: -
A27: 26 | B27: SASKIA NAYLA FAUZIYAH | C27: 2878 | D27: 26 | E27: =TEXT(F27,"[$-2000000]0") -> ٩ | F27: 9 | G27: 9 | H27: 9 | I27: 9 | J27: 9 | K27: 9 | L27: - | M27: 9 | N27: 9 | O27: 9 | P27: 9 | Q27: 9 | R27: 9 | S27: 8 | T27: =SUM(E27:S27) -> 116 | U27: 1 | V27: -
A28: 27 | B28: SILVY FATIYYA MAUDIDA | C28: 2880 | D28: 27 | E28: =TEXT(F28,"[$-2000000]0") -> ٦ | F28: 6 | G28: 7 | H28: 9 | I28: 5 | J28: 4 | K28: 8 | L28: - | M28: 7 | N28: 7 | O28: 6 | P28: 8 | Q28: 7 | R28: 8 | S28: 8 | T28: =SUM(E28:S28) -> 90 | U28: - | V28: 2
A29: 28 | B29: UMI KULTSUM | C29: 2850 | D29: 28 | E29: =TEXT(F29,"[$-2000000]0") -> ٥ | F29: 5 | G29: 7 | H29: 9 | I29: 4 | J29: 6 | K29: 4 | L29: - | M29: 8 | N29: 7 | O29: 5 | P29: 8 | Q29: 8 | R29: 9 | S29: 8 | T29: =SUM(E29:S29) -> 88 | U29: - | V29: -
A30: 29 | B30: UMMU NAFISAH SALMA | C30: 2752 | D30: 29 | E30: =TEXT(F30,"[$-2000000]0") -> ٧ | F30: 7 | G30: 9 | H30: 8 | I30: 4 | J30: 5 | K30: 6 | L30: - | M30: 5 | N30: 4 | O30: 7 | P30: 8 | Q30: 8 | R30: 9 | S30: 8 | T30: =SUM(E30:S30) -> 88 | U30: - | V30: -
A31: 30 | B31: VIA HIKMATUL MAULA | C31: 2910 | D31: 30 | E31: =TEXT(F31,"[$-2000000]0") -> ٦ | F31: 6 | G31: 6 | H31: 6 | I31: 4 | J31: 4 | K31: 6 | L31: - | M31: 6 | N31: 4 | O31: 5 | P31: 7 | Q31: 7 | R31: 8 | S31: 7 | T31: =SUM(E31:S31) -> 76 | U31: - | V31: -
A32: 31 | B32: VINA HIMMATUL QUDSIYAH | C32: 4267 | D32: 31 | E32: =TEXT(F32,"[$-2000000]0") -> ٦ | F32: 6 | G32: 4 | H32: 5 | I32: 4 | J32: 4 | K32: 6 | L32: - | M32: 5 | N32: 4 | O32: 5 | P32: 7 | Q32: 6 | R32: 7 | S32: 7 | T32: =SUM(E32:S32) -> 70 | U32: - | V32: -
A33: 32 | B33: ZAHRA ALFIYATUNNISA | C33: 2882 | D33: 32 | E33: =TEXT(F33,"[$-2000000]0") -> ٥ | F33: 5 | G33: 5 | H33: 7 | I33: 6 | J33: 5 | K33: 8 | L33: - | M33: 8 | N33: 5 | O33: 8 | P33: 8 | Q33: 8 | R33: 8 | S33: 7 | T33: =SUM(E33:S33) -> 88 | U33: - | V33: -
A34: 33 | B34: ZIANA DEWI AISYAH | C34: 2720 | D34: 33 | E34: =TEXT(F34,"[$-2000000]0") -> ٧ | F34: 7 | G34: 6 | H34: 8 | I34: 5 | J34: 4 | K34: 8 | L34: - | M34: 7 | N34: 4 | O34: 7 | P34: 8 | Q34: 8 | R34: 8 | S34: 8 | T34: =SUM(E34:S34) -> 88 | U34: 2 | V34: 1
A35: 34 | B35: ZILDA KHAFYANA SARI MUNAZAH | C35: 2851 | D35: 34 | E35: =TEXT(F35,"[$-2000000]0") -> ٩ | F35: 9 | G35: 7 | H35: 9 | I35: 5 | J35: 7 | K35: 9 | L35: - | M35: 7 | N35: 6 | O35: 7 | P35: 8 | Q35: 8 | R35: 8 | S35: 8 | T35: =SUM(E35:S35) -> 98 | U35: 6 | V35: -
B36: NILAI 'AM | E36: =TEXT(F36,"[$-2000000]0") -> ٢٥٣ | F36: =SUM(F2:F35) -> 253 | G36: =SUM(G2:G35) -> 251 | H36: =SUM(H2:H35) -> 284 | I36: =SUM(I2:I35) -> 207 | J36: =SUM(J2:J35) -> 229 | K36: =SUM(K2:K35) -> 258 | L36: - | M36: =SUM(M2:M35) -> 253 | N36: =SUM(N2:N35) -> 231 | O36: =SUM(O2:O35) -> 256 | P36: =SUM(P2:P35) -> 272 | Q36: =SUM(Q2:Q35) -> 264 | R36: =SUM(R2:R35) -> 276 | S36: =SUM(S2:S35) -> 264 | T36: =SUM(E36:S36) -> 3298 | U36: - | V36: -
U37: - | V37: -
U38: - | V38: -
H40: NILAI 'AM
H41: =E36/D35 -> 7
...

Sheet 2 ALIYAH D
A1: No. Tamrin | B1: Nama | C1: No. Stambuk | D1: JML Siswi | E1: تفسير الجلالين | G1: إتمام الدراية | H1: رياض الصالحين | I1: كفاية العوام | J1: فتح المعين | K1: تسهيل الطرقات | L1: مبادئ قواعد الفقهية | M1: عدة الفارض | N1: الفية ابن مالك | O1: بداية الهداية | P1: الخط \ الإملاء | Q1: قراءة الكتب | R1: المحافظة | S1: الأخلاق | T1: جمل أرقام الدرجات الدراسية | U1: بإذن | V1: بغيره
A2: 01 | B2: ABIDAH SYAKIRAH | C2: 2651 | D2: 01 | E2: =TEXT(F2,"[$-2000000]0") -> ٥ | F2: 5 | G2: 8 | H2: 9 | I2: 6 | J2: 8 | K2: 8 | L2: - | M2: 8 | N2: 7 | O2: 7 | P2: 8 | Q2: 8 | R2: 8 | S2: 8 | T2: =SUM(E2:S2) -> 98 | U2: - | V2: 2
A3: 02 | B3: AISA DAFA AZALIA | C3: 2721 | D3: 02 | E3: =TEXT(F3,"[$-2000000]0") -> ٨ | F3: 8 | G3: 9 | H3: 9 | I3: 7 | J3: 8 | K3: 8 | L3: - | M3: 9 | N3: 6 | O3: 8 | P3: 8 | Q3: 8 | R3: 8 | S3: 8 | T3: =SUM(E3:S3) -> 104 | U3: - | V3: -
A4: 03 | B4: ARIFATUL KHUSNA | C4: 2726 | D4: 03 | E4: =TEXT(F4,"[$-2000000]0") -> ٦ | F4: 6 | G4: 6 | H4: 6 | I4: 4 | J4: 6 | K4: 4 | L4: - | M4: 8 | N4: 7 | O4: 6 | P4: 9 | Q4: 8 | R4: 7 | S4: 8 | T4: =SUM(E4:S4) -> 85 | U4: 1 | V4: -
A5: 04 | B5: ATINA MAHSUNAH | C5: 2793 | D5: 04 | E5: =TEXT(F5,"[$-2000000]0") -> ٨ | F5: 8 | G5: 8 | H5: 9 | I5: 9 | J5: 9 | K5: 9 | L5: - | M5: 9 | N5: 9 | O5: 9 | P5: 9 | Q5: 8 | R5: 8 | S5: 8 | T5: =SUM(E5:S5) -> 112 | U5: 5 | V5: -
A6: 05 | B6: DEWI FANIDA CAROLLINA | C6: 2821 | D6: 05 | E6: =TEXT(F6,"[$-2000000]0") -> ٧ | F6: 7 | G6: 7 | H6: 8 | I6: 4 | J6: 5 | K6: 6 | L6: - | M6: 8 | N6: 7 | O6: 7 | P6: 8 | Q6: 7 | R6: 7 | S6: 8 | T6: =SUM(E6:S6) -> 89 | U6: - | V6: -
A7: 06 | B7: DUWI BAKDIYATUL MUALIFAH | C7: 2757 | D7: 06 | E7: =TEXT(F7,"[$-2000000]0") -> ٧ | F7: 7 | G7: 6 | H7: 9 | I7: 4 | J7: 6 | K7: 4 | L7: - | M7: 8 | N7: 5 | O7: 7 | P7: 7 | Q7: 7 | R7: 7 | S7: 8 | T7: =SUM(E7:S7) -> 85 | U7: 4 | V7: 2
A8: 07 | B8: DWYKA FIRDANDHA TUNGGA WIJAYA | C8: 2758 | D8: 07 | E8: =TEXT(F8,"[$-2000000]0") -> ٨ | F8: 8 | G8: 6 | H8: 8 | I8: 5 | J8: 8 | K8: 6 | L8: - | M8: 8 | N8: 8 | O8: 8 | P8: 8 | Q8: 8 | R8: 7 | S8: 8 | T8: =SUM(E8:S8) -> 96 | U8: - | V8: -
A9: 08 | B9: FATIHATU DINIYAH | C9: 2857 | D9: 08 | E9: =TEXT(F9,"[$-2000000]0") -> ٧ | F9: 7 | G9: 8 | H9: 8 | I9: 7 | J9: 7 | K9: 8 | L9: - | M9: 9 | N9: 9 | O9: 7 | P9: 7 | Q9: 8 | R9: 8 | S9: 8 | T9: =SUM(E9:S9) -> 101 | U9: - | V9: -
A10: 09 | B10: GHINA NABILA | C10: 2733 | D10: 09 | E10: =TEXT(F10,"[$-2000000]0") -> ٥ | F10: 5 | G10: 6 | H10: 8 | I10: 5 | J10: 6 | K10: 6 | L10: - | M10: 6 | N10: 5 | O10: 7 | P10: 8 | Q10: 7 | R10: 8 | S10: 8 | T10: =SUM(E10:S10) -> 85 | U10: 1 | V10: -
A11: 10 | B11: ILYA AISYAH ROWI | C11: 2862 | D11: 10 | E11: =TEXT(F11,"[$-2000000]0") -> ٨ | F11: 8 | G11: 7 | H11: 9 | I11: 6 | J11: 7 | K11: 9 | L11: - | M11: 9 | N11: 9 | O11: 9 | P11: 8 | Q11: 8 | R11: 7 | S11: 8 | T11: =SUM(E11:S11) -> 104 | U11: 1 | V11: -
A12: 11 | B12: JINANI FIRDAUSHIYAH | C12: 2763 | D12: 11 | E12: =TEXT(F12,"[$-2000000]0") -> ٨ | F12: 8 | G12: 8 | H12: 7 | I12: 6 | J12: 9 | K12: 8 | L12: - | M12: 7 | N12: 9 | O12: 7 | P12: 8 | Q12: 8 | R12: 8 | S12: 8 | T12: =SUM(E12:S12) -> 101 | U12: 1 | V12: -
A13: 12 | B13: KEYSHA FATIMAH ATHAYAL ILAH | C13: 2764 | D13: 12 | E13: =TEXT(F13,"[$-2000000]0") -> ٦ | F13: 6 | G13: 7 | H13: 8 | I13: 4 | J13: 6 | K13: 5 | L13: - | M13: 4 | N13: 7 | O13: 7 | P13: 8 | Q13: 8 | R13: 8 | S13: 8 | T13: =SUM(E13:S13) -> 86 | U13: - | V13: -
A14: 13 | B14: KHOEROTIN BARIROH | C14: 2865 | D14: 13 | E14: =TEXT(F14,"[$-2000000]0") -> ٤ | F14: 4 | G14: 6 | H14: 7 | I14: 4 | J14: 6 | K14: 6 | L14: - | M14: 8 | N14: 4 | O14: 6 | P14: 8 | Q14: 7 | R14: 7 | S14: 8 | T14: =SUM(E14:S14) -> 81 | U14: - | V14: -
A15: 14 | B15: LUTFI HIDAYATUS SHOLIHAH | C15: 2831 | D15: 14 | E15: =TEXT(F15,"[$-2000000]0") -> ٨ | F15: 8 | G15: 9 | H15: 9 | I15: 9 | J15: 9 | K15: 9 | L15: - | M15: 9 | N15: 9 | O15: 8 | P15: 8 | Q15: 9 | R15: 8 | S15: 8 | T15: =SUM(E15:S15) -> 112 | U15: 1 | V15: -
A16: 15 | B16: MASFIATUL AULIA | C16: 2895 | D16: 15 | E16: =TEXT(F16,"[$-2000000]0") -> ٧ | F16: 7 | G16: 6 | H16: 9 | I16: 7 | J16: 7 | K16: 7 | L16: - | M16: 8 | N16: 7 | O16: 8 | P16: 8 | Q16: 8 | R16: 8 | S16: 8 | T16: =SUM(E16:S16) -> 98 | U16: 1 | V16: -
A17: 16 | B17: NAIL AL AMAL | C17: 2809 | D17: 16 | E17: =TEXT(F17,"[$-2000000]0") -> ٧ | F17: 7 | G17: 4 | H17: 8 | I17: 5 | J17: 5 | K17: 6 | L17: - | M17: 6 | N17: 5 | O17: 6 | P17: 9 | Q17: 8 | R17: 8 | S17: 8 | T17: =SUM(E17:S17) -> 85 | U17: - | V17: -
A18: 17 | B18: NAILA FATHIMAH AZZAHRO | C18: 2665 | D18: 17 | E18: =TEXT(F18,"[$-2000000]0") -> ٩ | F18: 9 | G18: 9 | H18: 9 | I18: 9 | J18: 9 | K18: 9 | L18: - | M18: 9 | N18: 9 | O18: 9 | P18: 9 | Q18: 9 | R18: 8 | S18: 8 | T18: =SUM(E18:S18) -> 115 | U18: 2 | V18: -
A19: 18 | B19: NAILLA SALSABILA FIRDAUSHI | C19: 2666 | D19: 18 | E19: =TEXT(F19,"[$-2000000]0") -> ٦ | F19: 6 | G19: 4 | H19: 8 | I19: 6 | J19: 6 | K19: 4 | L19: - | M19: 8 | N19: 5 | O19: 7 | P19: 8 | Q19: 8 | R19: 8 | S19: 8 | T19: =SUM(E19:S19) -> 86 | U19: 1 | V19: -
A20: 19 | B20: NAYLIZZULFA | C20: 2705 | D20: 19 | E20: =TEXT(F20,"[$-2000000]0") -> ٥ | F20: 5 | G20: 5 | H20: 8 | I20: 4 | J20: 7 | K20: 4 | L20: - | M20: 5 | N20: 4 | O20: 5 | P20: 7 | Q20: 7 | R20: 7 | S20: 8 | T20: =SUM(E20:S20) -> 76 | U20: 1 | V20: -
A21: 20 | B21: NENENG SAYYIDATUN HUMAIROH | C21: 2706 | D21: 20 | E21: =TEXT(F21,"[$-2000000]0") -> ٤ | F21: 4 | G21: 4 | H21: 5 | I21: 4 | J21: 4 | K21: 4 | L21: - | M21: 4 | N21: 4 | O21: 5 | P21: 8 | Q21: 7 | R21: 7 | S21: 8 | T21: =SUM(E21:S21) -> 68 | U21: - | V21: -
A22: 21 | B22: OKTA FADILA | C22: 2708 | D22: 21 | E22: =TEXT(F22,"[$-2000000]0") -> ٧ | F22: 7 | G22: 4 | H22: 8 | I22: 4 | J22: 6 | K22: 7 | L22: - | M22: 5 | N22: 5 | O22: 6 | P22: 8 | Q22: 7 | R22: 7 | S22: 8 | T22: =SUM(E22:S22) -> 82 | U22: 1 | V22: 1
A23: 22 | B23: PUTRI NAJWA AQILA | C23: 2841 | D23: 22 | E23: =TEXT(F23,"[$-2000000]0") -> ٤ | F23: 4 | G23: 4 | H23: 7 | I23: 4 | J23: 5 | K23: 5 | L23: - | M23: 4 | N23: 5 | O23: 5 | P23: 8 | Q23: 8 | R23: 7 | S23: 8 | T23: =SUM(E23:S23) -> 74 | U23: - | V23: -
A24: 23 | B24: PUTRINDA AYU BERLIANI | C24: 2812 | D24: 23 | E24: =TEXT(F24,"[$-2000000]0") -> ٦ | F24: 6 | G24: 4 | H24: 8 | I24: 4 | J24: 7 | K24: 5 | L24: - | M24: 6 | N24: 4 | O24: 8 | P24: 7 | Q24: 7 | R24: 7 | S24: 8 | T24: =SUM(E24:S24) -> 81 | U24: 1 | V24: -
A25: 24 | B25: RAIHANAH | C25: 2672 | D25: 24 | E25: =TEXT(F25,"[$-2000000]0") -> ٩ | F25: 9 | G25: 9 | H25: 9 | I25: 9 | J25: 9 | K25: 9 | L25: - | M25: 9 | N25: 9 | O25: 9 | P25: 8 | Q25: 8 | R25: 8 | S25: 8 | T25: =SUM(E25:S25) -> 113 | U25: - | V25: -
A26: 25 | B26: REVA ARDIANA FADILAH | C26: 2875 | D26: 25 | E26: =TEXT(F26,"[$-2000000]0") -> ٦ | F26: 6 | G26: 7 | H26: 9 | I26: 5 | J26: 6 | K26: 6 | L26: - | M26: 8 | N26: 4 | O26: 7 | P26: 7 | Q26: 8 | R26: 8 | S26: 8 | T26: =SUM(E26:S26) -> 89 | U26: 4 | V26: -
A27: 26 | B27: SA'IDAH FIDDAROINI | C27: 2845 | D27: 26 | E27: =TEXT(F27,"[$-2000000]0") -> ٥ | F27: 5 | G27: 6 | H27: 8 | I27: 5 | J27: 6 | K27: 4 | L27: - | M27: 6 | N27: 6 | O27: 8 | P27: 8 | Q27: 8 | R27: 8 | S27: 8 | T27: =SUM(E27:S27) -> 86 | U27: - | V27: -
A28: 27 | B28: SIFA MA'RIFATUL HASNA | C28: 2782 | D28: 27 | E28: =TEXT(F28,"[$-2000000]0") -> ٩ | F28: 9 | G28: 9 | H28: 9 | I28: 7 | J28: 7 | K28: 7 | L28: - | M28: 6 | N28: 6 | O28: 9 | P28: 9 | Q28: 8 | R28: 8 | S28: 8 | T28: =SUM(E28:S28) -> 102 | U28: 2 | V28: 1
A29: 28 | B29: SITI ASIAH | C29: 2751 | D29: 28 | E29: =TEXT(F29,"[$-2000000]0") -> ٨ | F29: 8 | G29: 5 | H29: 7 | I29: 5 | J29: 4 | K29: 6 | L29: - | M29: 7 | N29: 6 | O29: 7 | P29: 8 | Q29: 8 | R29: 8 | S29: 6 | T29: =SUM(E29:S29) -> 85 | U29: 2 | V29: 12
A30: 29 | B30: SITI ZIRAN NURFATWA | C30: 2907 | D30: 29 | E30: =TEXT(F30,"[$-2000000]0") -> ٩ | F30: 9 | G30: 9 | H30: 7 | I30: 7 | J30: 9 | K30: 8 | L30: - | M30: 8 | N30: 9 | O30: 8 | P30: 7 | Q30: 8 | R30: 8 | S30: 8 | T30: =SUM(E30:S30) -> 105 | U30: 1 | V30: -
A31: 30 | B31: ULFA ZAHROTUL 'ADNA | C31: 2849 | D31: 30 | E31: =TEXT(F31,"[$-2000000]0") -> ٦ | F31: 6 | G31: 7 | H31: 8 | I31: 5 | J31: 6 | K31: 6 | L31: - | M31: 9 | N31: 6 | O31: 7 | P31: 8 | Q31: 7 | R31: 8 | S31: 8 | T31: =SUM(E31:S31) -> 91 | U31: 1 | V31: -
A32: 31 | B32: YULIDA MAHARANI | C32: 2686 | D32: 31 | E32: =TEXT(F32,"[$-2000000]0") -> ٨ | F32: 8 | G32: 8 | H32: 9 | I32: 7 | J32: 9 | K32: 9 | L32: - | M32: 9 | N32: 9 | O32: 5 | P32: 8 | Q32: 8 | R32: 8 | S32: 8 | T32: =SUM(E32:S32) -> 105 | U32: 1 | V32: -
A33: 32 | B33: ZAHARA MAULIDIA SURATMAN PUTRI | C33: 2719 | D33: 32 | E33: =TEXT(F33,"[$-2000000]0") -> ٤ | F33: 4 | G33: 6 | H33: 7 | I33: 4 | J33: 5 | K33: 6 | L33: - | M33: 5 | N33: 7 | O33: 6 | P33: 8 | Q33: 7 | R33: 8 | S33: 8 | T33: =SUM(E33:S33) -> 81 | U33: 2 | V33: -
B34: NILAI 'AM | E34: =TEXT(F34,"[$-2000000]0") -> ٢١٤ | F34: =SUM(F2:F33) -> 214 | G34: =SUM(G2:G33) -> 211 | H34: =SUM(H2:H33) -> 257 | I34: =SUM(I2:I33) -> 181 | J34: =SUM(J2:J33) -> 217 | K34: =SUM(K2:K33) -> 208 | L34: - | M34: =SUM(M2:M33) -> 232 | N34: =SUM(N2:N33) -> 211 | O34: =SUM(O2:O33) -> 228 | P34: =SUM(P2:P33) -> 255 | Q34: =SUM(Q2:Q33) -> 248 | R34: =SUM(R2:R33) -> 245 | S34: =SUM(S2:S33) -> 254
H38: NILAI 'AM
H39: =E34/D33 -> 7
B40: KET: HER2 AN | H40: =G34/D33 -> 7
B41: PROBLEMATIC | H41: =H34/D33 -> 8
H42: =I34/D33 -> 6
H43: =J34/D33 -> 7
...

Sheet 2 ALIYAH E
A1: No. Tamrin | B1: Nama | C1: No. Stambuk | D1: JML Siswi | E1: تفسير الجلالين | G1: إتمام الدراية | H1: رياض الصالحين | I1: كفاية العوام | J1: فتح المعين | K1: تسهيل الطرقات | L1: مبادئ قواعد الفقهية | M1: عدة الفارض | N1: الفية ابن مالك | O1: بداية الهداية | P1: الخط \ الإملاء | Q1: قراءة الكتب | R1: المحافظة | S1: الأخلاق | T1: جمل أرقام الدرجات الدراسية | U1: بإذن | V1: بغيره
A2: 01 | B2: DEWI FATMAWATI | C2: 2754 | D2: 01 | E2: =TEXT(F2,"[$-2000000]0") -> ٨ | F2: 8 | G2: 8 | H2: 9 | I2: 5 | J2: 6 | K2: 8 | L2: - | M2: 8 | N2: 8 | O2: 6 | P2: 8 | Q2: 8 | R2: 8 | S2: 8 | T2: =SUM(E2:S2) -> 98 | U2: 7 | V2: -
A3: 02 | B3: DIAH AYU ROSITA | C3: 2755 | D3: 02 | E3: =TEXT(F3,"[$-2000000]0") -> ٩ | F3: 9 | G3: 6 | H3: 8 | I3: 5 | J3: 6 | K3: 7 | L3: - | M3: 9 | N3: 7 | O3: 8 | P3: 8 | Q3: 7 | R3: 8 | S3: 8 | T3: =SUM(E3:S3) -> 96 | U3: - | V3: -
A4: 03 | B4: DITYA KHAILILA KHUSNA | C4: 2823 | D4: 03 | E4: =TEXT(F4,"[$-2000000]0") -> ٩ | F4: 9 | G4: 8 | H4: 7 | I4: 6 | J4: 7 | K4: 6 | L4: - | M4: 9 | N4: 7 | O4: 7 | P4: 8 | Q4: 8 | R4: 8 | S4: 6 | T4: =SUM(E4:S4) -> 96 | U4: 12 | V4: 17
A5: 04 | B5: ELZA ALVIN NUR AMALIA | C5: 2824 | D5: 04 | E5: =TEXT(F5,"[$-2000000]0") -> ٩ | F5: 9 | G5: 8 | H5: 9 | I5: 6 | J5: 6 | K5: 9 | L5: - | M5: 8 | N5: 9 | O5: 8 | P5: 8 | Q5: 8 | R5: 8 | S5: 8 | T5: =SUM(E5:S5) -> 104 | U5: 2 | V5: -
A6: 05 | B6: ENI SUPRIATI NINGSIH | C6: 2825 | D6: 05 | E6: =TEXT(F6,"[$-2000000]0") -> ٥ | F6: 5 | G6: 5 | H6: 6 | I6: 5 | J6: 5 | K6: 5 | L6: - | M6: 5 | N6: 6 | O6: 5 | P6: 8 | Q6: 6 | R6: 7 | S6: 8 | T6: =SUM(E6:S6) -> 76 | U6: - | V6: -
A7: 06 | B7: FATHIMAH AL BATUL | C7: 2826 | D7: 06 | E7: =TEXT(F7,"[$-2000000]0") -> ٧ | F7: 7 | G7: 7 | H7: 8 | I7: 5 | J7: 5 | K7: 5 | L7: - | M7: 5 | N7: 6 | O7: 7 | P7: 8 | Q7: 8 | R7: 8 | S7: 8 | T7: =SUM(E7:S7) -> 87 | U7: 1 | V7: -
A8: 07 | B8: HANUM MASRUROH | C8: 2655 | D8: 07 | E8: =TEXT(F8,"[$-2000000]0") -> ٩ | F8: 9 | G8: 9 | H8: 9 | I8: 8 | J8: 7 | K8: 9 | L8: - | M8: 9 | N8: 9 | O8: 7 | P8: 8 | Q8: 8 | R8: 8 | S8: 8 | T8: =SUM(E8:S8) -> 108 | U8: - | V8: -
A9: 08 | B9: HASUNAH | C9: 2803 | D9: 08 | E9: =TEXT(F9,"[$-2000000]0") -> ٩ | F9: 9 | G9: 7 | H9: 8 | I9: 7 | J9: 9 | K9: 9 | L9: - | M9: 7 | N9: 8 | O9: 7 | P9: 8 | Q9: 8 | R9: 8 | S9: 8 | T9: =SUM(E9:S9) -> 103 | U9: - | V9: -
A10: 09 | B10: JESI LESTARI | C10: 2863 | D10: 09 | E10: =TEXT(F10,"[$-2000000]0") -> ٥ | F10: 5 | G10: 5 | H10: 7 | I10: 5 | J10: 5 | K10: 5 | L10: - | M10: 5 | N10: 5 | O10: 6 | P10: 8 | Q10: 6 | R10: 7 | S10: 8 | T10: =SUM(E10:S10) -> 77 | U10: - | V10: -
A11: 10 | B11: KIFA YATUT TAUBAH | C11: 2807 | D11: 10 | E11: =TEXT(F11,"[$-2000000]0") -> ٩ | F11: 9 | G11: 9 | H11: 9 | I11: 5 | J11: 8 | K11: 7 | L11: - | M11: 9 | N11: 8 | O11: 8 | P11: 8 | Q11: 8 | R11: 8 | S11: 8 | T11: =SUM(E11:S11) -> 104 | U11: 1 | V11: -
A12: 12 | B12: LUTFIA AZZAHRA | C12: 2869 | D12: 11 | E12: =TEXT(F12,"[$-2000000]0") -> ٧ | F12: 7 | G12: 9 | H12: 8 | I12: 6 | J12: 6 | K12: 8 | L12: - | M12: 9 | N12: 7 | O12: 7 | P12: 8 | Q12: 7 | R12: 8 | S12: 8 | T12: =SUM(E12:S12) -> 98 | U12: - | V12: -
A13: 13 | B13: MACHYA MAMLUATUL 'AZA | C13: 2738 | D13: 12 | E13: =TEXT(F13,"[$-2000000]0") -> ٨ | F13: 8 | G13: 9 | H13: 9 | I13: 8 | J13: 8 | K13: 9 | L13: - | M13: 9 | N13: 9 | O13: 9 | P13: 8 | Q13: 8 | R13: 8 | S13: 8 | T13: =SUM(E13:S13) -> 110 | U13: - | V13: -
A14: 14 | B14: MARYAM | C14: 2832 | D14: 13 | E14: =TEXT(F14,"[$-2000000]0") -> ٩ | F14: 9 | G14: 9 | H14: 9 | I14: 9 | J14: 9 | K14: 9 | L14: - | M14: 9 | N14: 9 | O14: 9 | P14: 8 | Q14: 9 | R14: 8 | S14: 8 | T14: =SUM(E14:S14) -> 114 | U14: - | V14: -
A15: 15 | B15: MAULA SAIDAH AYYAMI | C15: 2768 | D15: 14 | E15: =TEXT(F15,"[$-2000000]0") -> ٥ | F15: 5 | G15: 6 | H15: 8 | I15: 5 | J15: 5 | K15: 5 | L15: - | M15: 5 | N15: 5 | O15: 6 | P15: 8 | Q15: 7 | R15: 8 | S15: 7 | T15: =SUM(E15:S15) -> 80 | U15: - | V15: -
A16: 16 | B16: MU'MINATUL AZIZAH | C16: 2897 | D16: 15 | E16: =TEXT(F16,"[$-2000000]0") -> ٦ | F16: 6 | G16: 5 | H16: 8 | I16: 5 | J16: 5 | K16: 5 | L16: - | M16: 5 | N16: 5 | O16: 6 | P16: 9 | Q16: 7 | R16: 8 | S16: 8 | T16: =SUM(E16:S16) -> 82 | U16: - | V16: -
A17: 17 | B17: NAFISA NAJWA FIMA FILLAH | C17: 2741 | D17: 16 | E17: =TEXT(F17,"[$-2000000]0") -> ٩ | F17: 9 | G17: 9 | H17: 9 | I17: 9 | J17: 8 | K17: 9 | L17: - | M17: 9 | N17: 9 | O17: 8 | P17: 9 | Q17: 9 | R17: 8 | S17: 8 | T17: =SUM(E17:S17) -> 113 | U17: 1 | V17: -
A18: 18 | B18: NAILA ALFA FAUZA | C18: 2898 | D18: 17 | E18: =TEXT(F18,"[$-2000000]0") -> ٨ | F18: 8 | G18: 8 | H18: 9 | I18: 6 | J18: 5 | K18: 6 | L18: - | M18: 9 | N18: 7 | O18: 5 | P18: 8 | Q18: 8 | R18: 8 | S18: 8 | T18: =SUM(E18:S18) -> 95 | U18: - | V18: -
A19: 19 | B19: NAJUA ZASKIA | C19: 2835 | D19: 18 | E19: =TEXT(F19,"[$-2000000]0") -> ٧ | F19: 7 | G19: 9 | H19: 8 | I19: 9 | J19: 6 | K19: 9 | L19: - | M19: 8 | N19: 9 | O19: 8 | P19: 8 | Q19: 8 | R19: 8 | S19: 8 | T19: =SUM(E19:S19) -> 105 | U19: 1 | V19: -
A20: 20 | B20: NIDA QOTHRUNNADA | C20: 2774 | D20: 19 | E20: =TEXT(F20,"[$-2000000]0") -> ٩ | F20: 9 | G20: 9 | H20: 9 | I20: 9 | J20: 9 | K20: 9 | L20: - | M20: 9 | N20: 9 | O20: 7 | P20: 8 | Q20: 8 | R20: 8 | S20: 8 | T20: =SUM(E20:S20) -> 111 | U20: 1 | V20: -
A21: 21 | B21: NUR WARDAH FAUZIYAH | C21: 2745 | D21: 20 | E21: =TEXT(F21,"[$-2000000]0") -> ٩ | F21: 9 | G21: 9 | H21: 9 | I21: 7 | J21: 8 | K21: 9 | L21: - | M21: 9 | N21: 9 | O21: 8 | P21: 8 | Q21: 9 | R21: 8 | S21: 8 | T21: =SUM(E21:S21) -> 110 | U21: - | V21: -
A22: 22 | B22: NURINDRA HANUM RAMADHANI | C22: 2839 | D22: 21 | E22: =TEXT(F22,"[$-2000000]0") -> ٥ | F22: 5 | G22: 6 | H22: 9 | I22: 5 | J22: 5 | K22: 5 | L22: - | M22: 8 | N22: 5 | O22: 7 | P22: 8 | Q22: 7 | R22: 8 | S22: 7 | T22: =SUM(E22:S22) -> 85 | U22: 2 | V22: 3
A23: 23 | B23: QUMI LAILATAZ ZULFA | C23: 2777 | D23: 22 | E23: =TEXT(F23,"[$-2000000]0") -> ٧ | F23: 7 | G23: 9 | H23: 9 | I23: 8 | J23: 7 | K23: 9 | L23: - | M23: 7 | N23: 9 | O23: 8 | P23: 8 | Q23: 8 | R23: 8 | S23: 8 | T23: =SUM(E23:S23) -> 105 | U23: 1 | V23: -
A24: 24 | B24: QURROTA A'YUN | C24: 2778 | D24: 23 | E24: =TEXT(F24,"[$-2000000]0") -> ٦ | F24: 6 | G24: 5 | H24: 8 | I24: 5 | J24: 5 | K24: 5 | L24: - | M24: 5 | N24: 5 | O24: 5 | P24: 8 | Q24: 7 | R24: 8 | S24: 8 | T24: =SUM(E24:S24) -> 80 | U24: - | V24: 2
A25: 25 | B25: RIFDA ISMATUL AZIZAH | C25: 2813 | D25: 24 | E25: =TEXT(F25,"[$-2000000]0") -> ٦ | F25: 6 | G25: 8 | H25: 7 | I25: 5 | J25: 7 | K25: 5 | L25: - | M25: 5 | N25: 6 | O25: 5 | P25: 8 | Q25: 6 | R25: 8 | S25: 8 | T25: =SUM(E25:S25) -> 84 | U25: - | V25: -
A26: 26 | B26: RIZQI DAIMATUL KHUSNA | C26: 2915 | D26: 25 | E26: =TEXT(F26,"[$-2000000]0") -> ٦ | F26: 6 | G26: 5 | H26: 7 | I26: 7 | J26: 5 | K26: 5 | L26: - | M26: 5 | N26: 5 | O26: 5 | P26: 8 | Q26: 6 | R26: 7 | S26: 8 | T26: =SUM(E26:S26) -> 79 | U26: 2 | V26: 2
A27: 27 | B27: ROFIQOH ANISA ZAHRA | C27: 2781 | D27: 26 | E27: =TEXT(F27,"[$-2000000]0") -> ٩ | F27: 9 | G27: 8 | H27: 9 | I27: 8 | J27: 7 | K27: 8 | L27: - | M27: 9 | N27: 8 | O27: 8 | P27: 8 | Q27: 8 | R27: 8 | S27: 8 | T27: =SUM(E27:S27) -> 106 | U27: - | V27: 1
A28: 28 | B28: SAFIRA SALSABILA | C28: 2877 | D28: 27 | E28: =TEXT(F28,"[$-2000000]0") -> ٦ | F28: 6 | G28: 5 | H28: 7 | I28: 6 | J28: 5 | K28: 6 | L28: - | M28: 8 | N28: 7 | O28: 7 | P28: 8 | Q28: 7 | R28: 8 | S28: 8 | T28: =SUM(E28:S28) -> 88 | U28: 2 | V28: -
A29: 29 | B29: SHOFIYATUL MUHSINAH | C29: 2710 | D29: 28 | E29: =TEXT(F29,"[$-2000000]0") -> ٥ | F29: 5 | G29: 7 | H29: 8 | I29: 6 | J29: 6 | K29: 7 | L29: - | M29: 5 | N29: 8 | O29: 6 | P29: 8 | Q29: 8 | R29: 8 | S29: 8 | T29: =SUM(E29:S29) -> 90 | U29: - | V29: -
A30: 30 | B30: TAQIATUL ALIYAH | C30: 2712 | D30: 29 | E30: =TEXT(F30,"[$-2000000]0") -> ٥ | F30: 5 | G30: 5 | H30: 6 | I30: 5 | J30: 5 | K30: 5 | L30: - | M30: 5 | N30: 5 | O30: 5 | P30: 8 | Q30: 6 | R30: 7 | S30: 8 | T30: =SUM(E30:S30) -> 75 | U30: - | V30: -
A31: 31 | B31: TSUAIBATUL ASLAMIYAH | C31: 2785 | D31: 30 | E31: =TEXT(F31,"[$-2000000]0") -> ٦ | F31: 6 | G31: 5 | H31: 8 | I31: 5 | J31: 5 | K31: 5 | L31: - | M31: 6 | N31: 5 | O31: 5 | P31: 8 | Q31: 7 | R31: 7 | S31: 7 | T31: =SUM(E31:S31) -> 79 | U31: - | V31: -
A32: 32 | B32: TSUROYYAH | C32: 2683 | D32: 31 | E32: =TEXT(F32,"[$-2000000]0") -> ٧ | F32: 7 | G32: 7 | H32: 8 | I32: 4 | J32: 5 | K32: 7 | L32: - | M32: 6 | N32: 4 | O32: 6 | P32: 8 | Q32: 8 | R32: 8 | S32: 7 | T32: =SUM(E32:S32) -> 85 | U32: 1 | V32: -
B33: NILAI 'AM | E33: =TEXT(F33,"[$-2000000]0") -> ٢٢٤ | F33: =SUM(F2:F32) -> 224 | G33: =SUM(G2:G32) -> 224 | H33: =SUM(H2:H32) -> 252 | I33: =SUM(I2:I32) -> 194 | J33: =SUM(J2:J32) -> 195 | K33: =SUM(K2:K32) -> 215 | L33: =SUM(L2:L32) -> 0 | M33: =SUM(M2:M32) -> 224 | ... S33: =SUM(S2:S32) -> 242 | U33: - | V33: -
U34: - | V34: -
U35: - | V35: -
H37: NILAI 'AM
H38: =E33/D32 -> 7
H39: =G33/D32 -> 7 | K39: nilai akhlaq turun 3 karna tidak izin 17
H40: =H33/D32 -> 8
H41: =I33/D32 -> 6
...

Sheet 2 ALIYAH F
A1: No. Tamrin | B1: Nama | C1: No. Stambuk | D1: JML Siswi | E1: تفسير الجلالين | G1: إتمام الدراية | H1: رياض الصالحين | I1: كفاية العوام | J1: فتح المعين | K1: تسهيل الطرقات | L1: مبادئ قواعد الفقهية | M1: عدة الفارض | N1: الفية ابن مالك | O1: بداية الهداية | P1: الخط \ الإملاء | Q1: قراءة الكتب | R1: المحافظة | S1: الأخلاق | T1: جمل أرقام الدرجات الدراسية | U1: بإذن | V1: بغيره
A2: 01 | B2: ALIYAH MIFTAHUL ULUM | C2: 2723 | D2: 01 | E2: =TEXT(F2,"[$-2000000]0") -> ٨ | F2: 8 | G2: 9 | H2: 8 | I2: 7 | J2: 7 | K2: 9 | L2: - | M2: 8 | N2: 7 | O2: 9 | P2: 8 | Q2: 7 | R2: 8 | S2: 8 | T2: =SUM(E2:S2) -> 103 | U2: 1 | V2: -
A3: 02 | B3: AMNA VADILLA | C3: 2819 | D3: 02 | E3: =TEXT(F3,"[$-2000000]0") -> ٧ | F3: 7 | G3: 8 | H3: 9 | I3: 6 | J3: 7 | K3: 8 | L3: - | M3: 9 | N3: 8 | O3: 9 | P3: 8 | Q3: 8 | R3: 8 | S3: 8 | T3: =SUM(E3:S3) -> 103 | U3: - | V3: -
A4: 03 | B4: AULA ZIANA ABIDAH | C4: 2887 | D4: 03 | E4: =TEXT(F4,"[$-2000000]0") -> ٩ | F4: 9 | G4: 9 | H4: 9 | I4: 9 | J4: 8 | K4: 9 | L4: - | M4: 9 | N4: 9 | O4: 9 | P4: 8 | Q4: 8 | R4: 8 | S4: 8 | T4: =SUM(E4:S4) -> 112 | U4: 2 | V4: -
A5: 04 | B5: AZIZAH ISTIKHOMAH | C5: 2795 | D5: 04 | E5: =TEXT(F5,"[$-2000000]0") -> ٧ | F5: 7 | G5: 6 | H5: 7 | I5: 5 | J5: 7 | K5: 5 | L5: - | M5: 9 | N5: 7 | O5: 6 | P5: 7 | Q5: 7 | R5: 7 | S5: 8 | T5: =SUM(E5:S5) -> 88 | U5: - | V5: 1
A6: 05 | B6: AZKA AZKIA | C6: 2853 | D6: 05 | E6: =TEXT(F6,"[$-2000000]0") -> ٩ | F6: 9 | G6: 9 | H6: 9 | I6: 9 | J6: 9 | K6: 9 | L6: - | M6: 8 | N6: 9 | O6: 9 | P6: 8 | Q6: 8 | R6: 8 | S6: 8 | T6: =SUM(E6:S6) -> 112 | U6: - | V6: -
A7: 06 | B7: BIKI ETHMANNA QOLBY | C7: 2820 | D7: 06 | E7: =TEXT(F7,"[$-2000000]0") -> ٩ | F7: 9 | G7: 9 | H7: 9 | I7: 9 | J7: 9 | K7: 9 | L7: - | M7: 9 | N7: 9 | O7: 8 | P7: 8 | Q7: 8 | R7: 8 | S7: 8 | T7: =SUM(E7:S7) -> 112 | U7: 7 | V7: -
A8: 07 | B8: CHASYIFA ANNUKHBA | C8: 2797 | D8: 07 | E8: =TEXT(F8,"[$-2000000]0") -> ٦ | F8: 6 | G8: 8 | H8: 8 | I8: 8 | J8: 7 | K8: 7 | L8: - | M8: 8 | N8: 7 | O8: 7 | P8: 8 | Q8: 8 | R8: 8 | S8: 8 | T8: =SUM(E8:S8) -> 98 | U8: 1 | V8: -
A9: 08 | B9: DINDA ANISATUL MUBAYYINAH | C9: 2756 | D9: 08 | E9: =TEXT(F9,"[$-2000000]0") -> ٨ | F9: 8 | G9: 8 | H9: 9 | I9: 8 | J9: 8 | K9: 6 | L9: - | M9: 6 | N9: 5 | O9: 9 | P9: 8 | Q9: 7 | R9: 8 | S9: 8 | T9: =SUM(E9:S9) -> 98 | U9: - | V9: -
A10: 09 | B10: FADHILA KHASANAH | C10: 2856 | D10: 09 | E10: =TEXT(F10,"[$-2000000]0") -> ٥ | F10: 5 | G10: 5 | H10: 6 | I10: 5 | J10: 5 | K10: 5 | L10: - | M10: 5 | N10: 5 | O10: 5 | P10: 7 | Q10: 7 | R10: 7 | S10: 8 | T10: =SUM(E10:S10) -> 75 | U10: - | V10: -
A11: 10 | B11: FATIMAH AZZAHRO | C11: 2858 | D11: 10 | E11: =TEXT(F11,"[$-2000000]0") -> ٩ | F11: 9 | G11: 9 | H11: 9 | I11: 9 | J11: 9 | K11: 9 | L11: - | M11: 9 | N11: 9 | O11: 9 | P11: 8 | Q11: 8 | R11: 8 | S11: 8 | T11: =SUM(E11:S11) -> 113 | U11: - | V11: -
A12: 11 | B12: ISMA FATIYAH | C12: 2829 | D12: 11 | E12: =TEXT(F12,"[$-2000000]0") -> ٧ | F12: 7 | G12: 6 | H12: 8 | I12: 5 | J12: 5 | K12: 5 | L12: - | M12: 7 | N12: 5 | O12: 6 | P12: 7 | Q12: 7 | R12: 7 | S12: 8 | T12: =SUM(E12:S12) -> 83 | U12: 3 | V12: 2
A13: 12 | B13: LISSARI NABILLA | C13: 2893 | D13: 12 | E13: =TEXT(F13,"[$-2000000]0") -> ٨ | F13: 8 | G13: 8 | H13: 7 | I13: 9 | J13: 7 | K13: 9 | L13: - | M13: 5 | N13: 7 | O13: 9 | P13: 8 | Q13: 8 | R13: 8 | S13: 8 | T13: =SUM(E13:S13) -> 101 | U13: - | V13: 1
A14: 13 | B14: LU'LUIL HILDA MUNAYYA | C14: 2868 | D14: 13 | E14: =TEXT(F14,"[$-2000000]0") -> ٦ | F14: 6 | G14: 7 | H14: 6 | I14: 6 | J14: 6 | K14: 6 | L14: - | M14: 9 | N14: 7 | O14: 6 | P14: 8 | Q14: 7 | R14: 8 | S14: 8 | T14: =SUM(E14:S14) -> 90 | U14: - | V14: -
A15: 14 | B15: LUBNA MISKA SHOLIHAH | C15: 2658 | D15: 14 | E15: =TEXT(F15,"[$-2000000]0") -> ٩ | F15: 9 | G15: 9 | H15: 9 | I15: 9 | J15: 9 | K15: 9 | L15: - | M15: 9 | N15: 9 | O15: 9 | P15: 8 | Q15: 8 | R15: 8 | S15: 8 | T15: =SUM(E15:S15) -> 113 | U15: 1 | V15: -
A16: 15 | B16: MADINATUL MUKARROMAH | C16: 2737 | D16: 15 | E16: =TEXT(F16,"[$-2000000]0") -> ٧ | F16: 7 | G16: 8 | H16: 9 | I16: 9 | J16: 8 | K16: 9 | L16: - | M16: 7 | N16: 9 | O16: 7 | P16: 8 | Q16: 8 | R16: 8 | S16: 8 | T16: =SUM(E16:S16) -> 105 | U16: 7 | V16: -
A17: 17 | B17: MAULIDIA TASYA RAFIKA | C17: ='[1]1 ALIYAH D'!C17:E52 -> 2768 | D17: 16 | E17: =TEXT(F17,"[$-2000000]0") -> ٦ | F17: 6 | G17: 5 | H17: 8 | I17: 5 | J17: 7 | K17: 5 | L17: - | M17: 5 | N17: 5 | O17: 6 | P17: 7 | Q17: 7 | R17: 8 | S17: 8 | T17: =SUM(E17:S17) -> 82 | U17: 1 | V17: 5
A18: 18 | B18: MILADIATUS SA'ADAH | C18: 2739 | D18: 17 | E18: =TEXT(F18,"[$-2000000]0") -> ٩ | F18: 9 | G18: 9 | H18: 9 | I18: 7 | J18: 7 | K18: 6 | L18: - | M18: 8 | N18: 6 | O18: 8 | P18: 8 | Q18: 8 | R18: 8 | S18: 8 | T18: =SUM(E18:S18) -> 101 | U18: - | V18: -
A19: 19 | B19: MUTIARA NUR AZIZAH | C19: 2662 | D19: 18 | E19: =TEXT(F19,"[$-2000000]0") -> ٩ | F19: 9 | G19: 7 | H19: 9 | I19: 7 | J19: 8 | K19: 9 | L19: - | M19: 9 | N19: 7 | O19: 6 | P19: 8 | Q19: 7 | R19: 8 | S19: 8 | T19: =SUM(E19:S19) -> 102 | U19: 1 | V19: -
A20: 20 | B20: NAILIL FITROH | C20: 2899 | D20: 19 | E20: =TEXT(F20,"[$-2000000]0") -> ٦ | F20: 6 | G20: 5 | H20: 7 | I20: 5 | J20: 8 | K20: 7 | L20: - | M20: 6 | N20: 5 | O20: 7 | P20: 8 | Q20: 7 | R20: 8 | S20: 8 | T20: =SUM(E20:S20) -> 87 | U20: 1 | V20: -
A21: 21 | B21: NOOR FATHIA WARDANIA | C21: 2743 | D21: 20 | E21: =TEXT(F21,"[$-2000000]0") -> ٩ | F21: 9 | G21: 9 | H21: 9 | I21: 9 | J21: 9 | K21: 9 | L21: - | M21: 9 | N21: 9 | O21: 9 | P21: 8 | Q21: 8 | R21: 8 | S21: 8 | T21: =SUM(E21:S21) -> 113 | U21: - | V21: -
A22: 22 | B22: NUR LAILATUL MAFRISKA | C22: 2775 | D22: 21 | E22: =TEXT(F22,"[$-2000000]0") -> ٨ | F22: 8 | G22: 7 | H22: 9 | I22: 8 | J22: 8 | K22: 7 | L22: - | M22: 7 | N22: 8 | O22: 7 | P22: 8 | Q22: 7 | R22: 7 | S22: 8 | T22: =SUM(E22:S22) -> 99 | U22: - | V22: -
A23: 23 | B23: RIMA IZZULMILA | C23: 2876 | D23: 22 | E23: =TEXT(F23,"[$-2000000]0") -> ٨ | F23: 8 | G23: 9 | H23: 9 | I23: 9 | J23: 8 | K23: 9 | L23: - | M23: 9 | N23: 6 | O23: 9 | P23: 8 | Q23: 8 | R23: 8 | S23: 8 | T23: =SUM(E23:S23) -> 108 | U23: 1 | V23: -
A24: 24 | B24: RIRA ADELIA SAPUTRI | C24: 2814 | D24: 23 | E24: =TEXT(F24,"[$-2000000]0") -> ٧ | F24: 7 | G24: 8 | H24: 7 | I24: 6 | J24: 5 | K24: 6 | L24: - | M24: 5 | N24: 6 | O24: 7 | P24: 8 | Q24: 7 | R24: 7 | S24: 8 | T24: =SUM(E24:S24) -> 87 | U24: 1 | V24: 1
A25: 25 | B25: ROUDLOTUL FIRDAUSIL HUSNA | C25: 2747 | D25: 24 | E25: =TEXT(F25,"[$-2000000]0") -> ٧ | F25: 7 | G25: 9 | H25: 9 | I25: 9 | J25: 7 | K25: 8 | L25: - | M25: 7 | N25: 5 | O25: 7 | P25: 7 | Q25: 7 | R25: 7 | S25: 8 | T25: =SUM(E25:S25) -> 97 | U25: - | V25: 1
A26: 26 | B26: SALMA NUR JANNAH | C26: 2749 | D26: 25 | E26: =TEXT(F26,"[$-2000000]0") -> ٥ | F26: 5 | G26: 5 | H26: 8 | I26: 7 | J26: 6 | K26: 5 | L26: - | M26: 7 | N26: 5 | O26: 6 | P26: 8 | Q26: 7 | R26: 8 | S26: 8 | T26: =SUM(E26:S26) -> 85 | U26: 1 | V26: -
A27: 27 | B27: SHERLINA CAHYA NINGRUM | C27: 2879 | D27: 26 | E27: =TEXT(F27,"[$-2000000]0") -> ٩ | F27: 9 | G27: 9 | H27: 9 | I27: 8 | J27: 9 | K27: 9 | L27: - | M27: 8 | N27: 9 | O27: 9 | P27: 8 | Q27: 8 | R27: 8 | S27: 8 | T27: =SUM(E27:S27) -> 111 | U27: 6 | V27: -
A28: 28 | B28: SITI MALIKATUROHMAH | C28: 2906 | D28: 27 | E28: =TEXT(F28,"[$-2000000]0") -> ٨ | F28: 8 | G28: 6 | H28: 9 | I28: 6 | J28: 6 | K28: 5 | L28: - | M28: 5 | N28: 5 | O28: 7 | P28: 7 | Q28: 7 | R28: 8 | S28: 8 | T28: =SUM(E28:S28) -> 87 | U28: - | V28: -
A29: 29 | B29: SURINAH | C29: 2784 | D29: 28 | E29: =TEXT(F29,"[$-2000000]0") -> ٧ | F29: 7 | G29: 8 | H29: 8 | I29: 7 | J29: 6 | K29: 6 | L29: - | M29: 7 | N29: 6 | O29: 8 | P29: 8 | Q29: 7 | R29: 7 | S29: 7 | T29: =SUM(E29:S29) -> 92 | U29: 2 | V29: -
A30: 30 | B30: SYAKIRA GHINA FALIHA | C30: 2711 | D30: 29 | E30: =TEXT(F30,"[$-2000000]0") -> ٩ | F30: 9 | G30: 9 | H30: 9 | I30: 8 | J30: 8 | K30: 8 | L30: - | M30: 8 | N30: 9 | O30: 5 | P30: 8 | Q30: 7 | R30: 8 | S30: 8 | T30: =SUM(E30:S30) -> 104 | U30: - | V30: -
A31: 31 | B31: ZAHRO' NAILUL ULYA | C31: 2883 | D31: 30 | E31: =TEXT(F31,"[$-2000000]0") -> ٩ | F31: 9 | G31: 8 | H31: 9 | I31: 9 | J31: 9 | K31: 8 | L31: - | M31: 8 | N31: 9 | O31: 9 | P31: 8 | Q31: 8 | R31: 8 | S31: 8 | T31: =SUM(E31:S31) -> 110 | U31: - | V31: -
A32: 32 | B32: ZULFA HAFIFAH | C32: 2914 | D32: 31 | E32: =TEXT(F32,"[$-2000000]0") -> ٩ | F32: 9 | G32: 8 | H32: 9 | I32: 9 | J32: 8 | K32: 9 | L32: - | M32: 7 | N32: 7 | O32: 9 | P32: 8 | Q32: 8 | R32: 8 | S32: 8 | T32: =SUM(E32:S32) -> 107 | U32: - | V32: -
B33: NILAI 'AM | E33: =TEXT(F33,"[$-2000000]0") -> ٢٣٩ | F33: =SUM(F2:F32) -> 239 | G33: =SUM(G2:G32) -> 239 | H33: =SUM(H2:H32) -> 259 | I33: =SUM(I2:I32) -> 232 | J33: =SUM(J2:J32) -> 230 | K33: =SUM(K2:K32) -> 230 | L33: - | M33: =SUM(M2:M32) -> 232 | N33: =SUM(N2:N32) -> 219 | O33: =SUM(O2:O32) -> 236 | P33: =SUM(P2:P32) -> 242 | Q33: =SUM(Q2:Q32) -> 232 | R33: =SUM(R2:R32) -> 241 | S33: =SUM(S2:S32) -> 247 | U33: - | V33: -
U34: - | V34: -
V35: -
H37: NILAI 'AM
H38: =E33/D32 -> 8
H39: =G33/D32 -> 8
H40: =H33/D32 -> 8
H41: =I33/D32 -> 7
...

Sheet 2 ALIYAH G
A1: No. Tamrin | B1: Nama | C1: No. Stambuk | D1: JML Siswi | E1: تفسير الجلالين | G1: إتمام الدراية | H1: رياض الصالحين | I1: كفاية العوام | J1: فتح المعين | K1: تسهيل الطرقات | L1: مبادئ قواعد الفقهية | M1: عدة الفارض | N1: الفية ابن مالك | O1: بداية الهداية | P1: الخط \ الإملاء | Q1: قراءة الكتب | R1: المحافظة | S1: الأخلاق | T1: جمل أرقام الدرجات الدراسية | U1: بإذن | V1: بغيره
A2: 01 | B2: AISYATUL FIRDAUSY | C2: 2789 | D2: 01 | E2: =TEXT(F2,"[$-2000000]0") -> ٩ | F2: 9 | G2: 9 | H2: 9 | I2: 7 | J2: 9 | K2: 9 | L2: - | M2: 7 | N2: 9 | O2: 7 | P2: 9 | Q2: 9 | R2: 8 | S2: 8 | T2: =SUM(E2:S2) -> 109 | U2: 1 | V2: -
A3: 02 | B3: ALFA PUTRI AZZAHRA | C3: 2790 | D3: 02 | E3: =TEXT(F3,"[$-2000000]0") -> ٩ | F3: 9 | G3: 9 | H3: 9 | I3: 9 | J3: 9 | K3: 9 | L3: - | M3: 6 | N3: 9 | O3: 9 | P3: 7 | Q3: 8 | R3: 8 | S3: 8 | T3: =SUM(E3:S3) -> 109 | U3: - | V3: -
A4: 03 | B4: AMALIA NADLILAH | C4: 2724 | D4: 03 | E4: =TEXT(F4,"[$-2000000]0") -> ٨ | F4: 8 | G4: 5 | H4: 7 | I4: 7 | J4: 6 | K4: 7 | L4: - | M4: 6 | N4: 7 | O4: 5 | P4: 8 | Q4: 7 | R4: 7 | S4: 8 | T4: =SUM(E4:S4) -> 88 | U4: 1 | V4: -
A5: 04 | B5: ANNISA 'ULFATUN NAHDIYAH | C5: 2688 | D5: 04 | E5: =TEXT(F5,"[$-2000000]0") -> ٨ | F5: 8 | G5: 8 | H5: 8 | I5: 8 | J5: 6 | K5: 8 | L5: - | M5: 9 | N5: 8 | O5: 8 | P5: 8 | Q5: 8 | R5: 8 | S5: 8 | T5: =SUM(E5:S5) -> 103 | U5: 4 | V5: 5
A6: 05 | B6: ANNISA NIDAUL HUSNA | C6: 2886 | D6: 05 | E6: =TEXT(F6,"[$-2000000]0") -> ٦ | F6: 6 | G6: 5 | H6: 8 | I6: 4 | J6: 4 | K6: 5 | L6: - | M6: 7 | N6: 6 | O6: 5 | P6: 7 | Q6: 7 | R6: 7 | S6: 8 | T6: =SUM(E6:S6) -> 79 | U6: - | V6: -
A7: 07 | B7: AULIA NAFAIDA | C7: 2794 | D7: 06 | E7: =TEXT(F7,"[$-2000000]0") -> ٩ | F7: 9 | G7: 9 | H7: 9 | I7: 9 | J7: 9 | K7: 9 | L7: - | M7: 9 | N7: 9 | O7: 9 | P7: 9 | Q7: 8 | R7: 8 | S7: 8 | T7: =SUM(E7:S7) -> 114 | U7: - | V7: -
A8: 08 | B8: DARISSALMA | C8: 2753 | D8: 07 | E8: =TEXT(F8,"[$-2000000]0") -> ٨ | F8: 8 | G8: 7 | H8: 4 | I8: 8 | J8: 5 | K8: 9 | L8: - | M8: 5 | N8: 7 | O8: 8 | P8: 8 | Q8: 7 | R8: 7 | S8: 8 | T8: =SUM(E8:S8) -> 91 | U8: - | V8: -
A9: 10 | B9: DEWI NAYLA AZIZATUR ROHMAH | C9: 2798 | D9: 08 | E9: =TEXT(F9,"[$-2000000]0") -> ٩ | F9: 9 | G9: 9 | H9: 9 | I9: 9 | J9: 9 | K9: 9 | L9: - | M9: 9 | N9: 9 | O9: 6 | P9: 8 | Q9: 8 | R9: 7 | S9: 8 | T9: =SUM(E9:S9) -> 109 | U9: - | V9: -
A10: 11 | B10: DWI TRI MULYANI | C10: 2801 | D10: 09 | E10: =TEXT(F10,"[$-2000000]0") -> ٩ | F10: 9 | G10: 4 | H10: 8 | I10: 7 | J10: 6 | K10: 7 | L10: - | M10: 5 | N10: 4 | O10: 8 | P10: 8 | Q10: 7 | R10: 7 | S10: 8 | T10: =SUM(E10:S10) -> 88 | U10: - | V10: -
A11: 12 | B11: GHINAYA AFANI KHOLIDIA | C11: 2860 | D11: 10 | E11: =TEXT(F11,"[$-2000000]0") -> ٩ | F11: 9 | G11: 9 | H11: 9 | I11: 9 | J11: 9 | K11: 9 | L11: - | M11: 9 | N11: 9 | O11: 9 | P11: 9 | Q11: 9 | R11: 9 | S11: 8 | T11: =SUM(E11:S11) -> 116 | U11: 3 | V11: -
A12: 13 | B12: KAMALA SAFIRUL ARWA | C12: 2696 | D12: 11 | E12: =TEXT(F12,"[$-2000000]0") -> ٩ | F12: 9 | G12: 9 | H12: 9 | I12: 7 | J12: 4 | K12: 9 | L12: - | M12: 6 | N12: 8 | O12: 8 | P12: 8 | Q12: 7 | R12: 8 | S12: 8 | T12: =SUM(E12:S12) -> 100 | U12: - | V12: -
A13: 14 | B13: KHASNA NILNAL MUNA THOHA PUTRI | C13: 2864 | D13: 12 | E13: =TEXT(F13,"[$-2000000]0") -> ٩ | F13: 9 | G13: 9 | H13: 9 | I13: 9 | J13: 9 | K13: 9 | L13: - | M13: 9 | N13: 9 | O13: 9 | P13: 9 | Q13: 9 | R13: 8 | S13: 8 | T13: =SUM(E13:S13) -> 115 | U13: 1 | V13: -
A14: 15 | B14: KURNIA DWITA HAPSARI | C14: 2830 | D14: 13 | E14: =TEXT(F14,"[$-2000000]0") -> ٨ | F14: 8 | G14: 8 | H14: 7 | I14: 6 | J14: 4 | K14: 7 | L14: - | M14: 6 | N14: 4 | O14: 7 | P14: 7 | Q14: 8 | R14: 8 | S14: 8 | T14: =SUM(E14:S14) -> 88 | U14: 2 | V14: -
A15: 16 | B15: LU'LUATUL AZIZAH | C15: 2659 | D15: 14 | E15: =TEXT(F15,"[$-2000000]0") -> ٦ | F15: 6 | G15: 7 | H15: 8 | I15: 5 | J15: 7 | K15: 7 | L15: - | M15: 8 | N15: 5 | O15: 8 | P15: 7 | Q15: 7 | R15: 7 | S15: 8 | T15: =SUM(E15:S15) -> 90 | U15: 2 | V15: -
A16: 17 | B16: LUM'ATUNNISRINA | C16: 2736 | D16: 15 | E16: =TEXT(F16,"[$-2000000]0") -> ٨ | F16: 8 | G16: 9 | H16: 9 | I16: 7 | J16: 5 | K16: 7 | L16: - | M16: 9 | N16: 7 | O16: 8 | P16: 8 | Q16: 8 | R16: 8 | S16: 8 | T16: =SUM(E16:S16) -> 101 | U16: 3 | V16: -
A17: 18 | B17: NABILA NAILI ALVI KAROMAH | C17: 2873 | D17: 16 | E17: =TEXT(F17,"[$-2000000]0") -> ٨ | F17: 8 | G17: 7 | H17: 9 | I17: 5 | J17: 7 | K17: 9 | L17: - | M17: 9 | N17: 8 | O17: 6 | P17: 8 | Q17: 8 | R17: 8 | S17: 8 | T17: =SUM(E17:S17) -> 100 | U17: 2 | V17: -
A18: 19 | B18: NADYA IZZATUL MAULA SALSABILA | C18: 2770 | D18: 17 | E18: =TEXT(F18,"[$-2000000]0") -> ٩ | F18: 9 | G18: 8 | H18: 7 | I18: 6 | J18: 8 | K18: 9 | L18: - | M18: 7 | N18: 7 | O18: 8 | P18: 8 | Q18: 8 | R18: 8 | S18: 8 | T18: =SUM(E18:S18) -> 101 | U18: - | V18: -
A19: 20 | B19: NAELA AENAN NABILAH | C19: 2740 | D19: 18 | E19: =TEXT(F19,"[$-2000000]0") -> ٩ | F19: 9 | G19: 8 | H19: 7 | I19: 4 | J19: 7 | K19: 7 | L19: - | M19: 7 | N19: 6 | O19: 9 | P19: 7 | Q19: 7 | R19: 8 | S19: 8 | T19: =SUM(E19:S19) -> 94 | U19: - | V19: -
